Workbook
Name 신규상품: 피벗!$BJ$5:$CI$100

Sheet 원시
K3: 6 | L3: 9 | M3: 18 | N3: 19 | O3: 24 | P3: 25 | Q3: 40 | R3: 41 | S3: 42 | T3: 43 | U3: 56 | V3: 57 | W3: 58 | X3: 59 | Y3: 61 | Z3: 62 | AA3: 63 | AB3: 66 | AC3: 82 | AD3: 84
A4: 법인단 | B4: 영업부 | C4: 팀 | D4: 영업사원 | E4: 관리고객ID | F4: 관리고객명 | G4: 고객분류 | H4: 계층유형 | I4: 법인등록번호 | J4: 사업자번호 | K4: 계층유형 | L4: 사업상태 | M4: Biz 업종1 | N4: Biz 업종2 | O4: 114업종 | P4: 회선수 | Q4: 기업규모 | R4: 기업형태 | S4: 설립형태 | T4: 기업상태 | U4: 지번주소 | V4: 지번상세주소 | W4: 전화번호 | X4: 제품명 | Y4: 도로명주소 | Z4: 도로명상세주소 | AA4: 근로자수총합 | AB4: 신용등급 | AC4: 신업종명 | AD4: 재무업종명
A5: 경북법인고객담당 | B5: 법인고객영업2부 | C5: 법인고객영업2팀 | D5: 정연오 | E5: L0000020275 | F5: 흥해농업협동조합 | G5: 법인가치고객 | H5: 본사 | AF5: =COUNTIFS($E:$E,E5) -> 1
A6: 경북법인고객담당 | B6: 법인고객영업1부 | C6: 법인고객영업1팀 | D6: 권항구 | E6: L0001763305 | F6: 현서면사무소 | G6: 법인가치고객 | H6: 본사 | J6: 5088301826 | K6: 본사 | L6: 정상 | M6: 지자체/공공 | N6: 공공 | O6: Public>공공>정부/관청>면사무소 | P6: 19 | AA6: 0 | AF6: =COUNTIFS($E:$E,E6) -> 1
A7: 경북법인고객담당 | B7: 법인고객영업1부 | C7: 법인고객영업1팀 | D7: 권항구 | E7: L0000223181 | F7: 현서농업협동조합 | G7: 법인가치고객 | H7: 본사 | I7: 1744360000123 | J7: 5088200586 | K7: 본사 | L7: 정상 | M7: 금융 | N7: 공통 | O7: Retail/Service>도소매>자동차관련 판매>주유소 | P7: 22 | Q7: 판단제외대상 | R7: 조합 | S7: 신규설립(개업) | T7: 정상 | U7: 경북 청송군 현서면 | V7: 구산리 100-6번지 | Y7: 경북 청송군 현서면 구산북로 | Z7: 63 (구산리,농협하나로마트) | AA7: 26 | AC7: 산업 단체 | AF7: =COUNTIFS($E:$E,E7) -> 1
A8: 경북법인고객담당 | B8: 법인고객영업2부 | C8: 법인고객영업2팀 | D8: 오다영 | E8: 0D99FI5JM5G | F8: 현대피엔에스(주) | G8: 법인가치고객 | H8: 본사 | K8: 본사 | L8: 정상 | M8: 제조업 | N8: 기업 | P8: 1 | Q8: 중견기업 | R8: 주식회사 | S8: 신규설립(개업) | T8: 정상 | U8: 서울 강남구 삼성1동 | V8: 157-37번지 위워크빌딩 16층 | Y8: 서울 강남구 테헤란로 | Z8: 507, 16층 (삼성동,위워크빌딩) | AA8: 45 | AB8: A- | AC8: 그외 기타 일반목적용 기계 제조업 | AD8: 제조업 | AF8: =COUNTIFS($E:$E,E8) -> 1
A9: 경북법인고객담당 | B9: 법인고객영업3부 | C9: 법인고객영업1팀 | D9: 황현철 | E9: L0000025091 | F9: 해평단위농업협동조합 | G9: 핵심고객 | H9: 본사 | I9: 1753360000116 | J9: 5138206374 | K9: 본사 | L9: 정상 | M9: 금융 | N9: 공통 | O9: Finance>금융>은행>농협 | P9: 1 | Q9: 판단제외대상 | R9: 조합 | S9: 신규설립(개업) | T9: 정상 | U9: 경북 구미시 해평면 | V9: 낙성리 58-3번지 | W9: 054 474 4205 | X9: 농협, 금융, 도매 | Y9: 경북 구미시 해평면 해평시장1길 | Z9: 6 (낙성리) | AA9: 45 | AB9: BBB- | AC9: 신용조합 | AD9: 제조업 | AF9: =COUNTIFS($E:$E,E9) -> 1
A10: 경북법인고객담당 | B10: 법인고객영업3부 | C10: 법인고객영업2팀 | D10: 박종섭 | E10: L0000010808 | F10: 한보전설주식회사 | G10: 핵심고객 | H10: 본사 | I10: 1760110027761 | J10: 5138124583 | K10: 사업장 | L10: 정상 | M10: 건설업 | N10: 건설/호텔 | O10: Manufacture>중공업>건설>건물건설-종합 | P10: 22 | Q10: 중기업 | R10: 주식회사 | S10: 신규설립(개업) | T10: 정상 | U10: 경북 구미시 임은동 | V10: 666-2번지 | W10: 051 461 0799 | X10: 전기공사, 소방공사, 정보통신공사 | Y10: 경북 구미시 임은길 | Z10: 55-15 (임은동) | AA10: 24 | AB10: BBB- | AC10: 일반전기 공사업 | AD10: 제조업 | AF10: =COUNTIFS($E:$E,E10) -> 1
A11: 경북법인고객담당 | B11: 법인고객영업2부 | C11: 법인고객영업2팀 | D11: 이대석 | E11: 1-I53FFA | F11: 한맥건설(주) | G11: 법인가치고객 | H11: 본사 | I11: 1711110005240 | J11: 5088106230 | K11: 본사 | L11: 정상 | M11: 건설업 | N11: 건설/호텔 | O11: Manufacture>중공업>건설>건설업-종합 | P11: 5 | Q11: 소상공인 | R11: 주식회사 | S11: 신규설립(개업) | T11: 정상 | U11: 경북 안동시 옥동 | V11: 987-10번지 메트로오피스텔 803호 | W11: 054 852 7101 | X11: 철근콘크리트, 토공사 | Y11: 경북 안동시 복주5길 | Z11: 41, 803호 (옥동,메트로오피스텔) | AA11: 4 | AB11: BBB- | AC11: 철근 및 철근콘크리트 공사업 | AD11: 제조업 | AF11: =COUNTIFS($E:$E,E11) -> 2
A12: 경북법인고객담당 | B12: 법인고객영업2부 | C12: 법인고객영업2팀 | D12: 조영욱 | E12: 1-I53FFA | F12: 한맥건설(주) | G12: 법인가치고객 | H12: 본사 | I12: 1711110005240 | J12: 5088106230 | K12: 본사 | L12: 정상 | M12: 건설업 | N12: 건설/호텔 | O12: Manufacture>중공업>건설>건설업-종합 | P12: 5 | Q12: 소상공인 | R12: 주식회사 | S12: 신규설립(개업) | T12: 정상 | U12: 경북 안동시 옥동 | V12: 987-10번지 메트로오피스텔 803호 | W12: 054 852 7101 | X12: 철근콘크리트, 토공사 | Y12: 경북 안동시 복주5길 | Z12: 41, 803호 (옥동,메트로오피스텔) | AA12: 4 | AB12: BBB- | AC12: 철근 및 철근콘크리트 공사업 | AD12: 제조업 | AF12: =COUNTIFS($E:$E,E12) -> 2
A13: 경북법인고객담당 | B13: 법인고객영업3부 | C13: 법인고객영업1팀 | D13: 고한용 | E13: A0001350851 | F13: 한두레축산영농조합법인 | G13: 법인가치고객 | H13: 본사 | I13: 1754710002447 | J13: 5118112058 | K13: 본사 | L13: 정상 | M13: 판매업 | N13: 공통 | O13: Retail/Service>도소매>생활재 판매>사료도매 | P13: 10 | Q13: 소기업 | R13: 기타법인 | S13: 신규설립(개업) | T13: 정상 | U13: 경북 문경시 산양면 | V13: 진정리 630-3번지 | W13: 054 554 1050 | X13: TMF 사료 외 | Y13: 경북 문경시 산양면 산양공단1길 | Z13: 28 (진정리) | AA13: 11 | AB13: BB- | AD13: 제조업 | AF13: =COUNTIFS($E:$E,E13) -> 1
A14: 경북법인고객담당 | B14: 법인고객영업2부 | C14: 법인고객영업2팀 | D14: 이대석 | E14: L0000014358 | F14: 한동재생공사 | G14: 법인가치고객 | H14: 본사 | AF14: =COUNTIFS($E:$E,E14) -> 2
A15: 경북법인고객담당 | B15: 법인고객영업2부 | C15: 법인고객영업2팀 | D15: 오다영 | E15: 0AAGEWRIC7Z | F15: 한국퓨얼셀주식회사 | G15: 법인가치고객 | H15: 본사 | K15: 본사 | L15: 청산/해산 | M15: 에너지 | N15: 에너지/환경 | O15: Retail/Service>서비스업>사업서비스업>엔지니어링서비스-전기전자공학 | P15: 1 | Q15: 대기업 | R15: 주식회사 | S15: 신규설립(개업) | T15: 청산/해산 | U15: 경북 포항시 북구 흥해읍 | V15: 죽천리 698-1번지 | W15: 054 250 1300 | X15: 경기도 화성, 서울 등 전국4개 사이트에 총 58.75MW의 전력공급이 가능한 연료전지를 설치.운영 | Y15: 경북 포항시 북구 흥해읍 영일만산단로88번길 | Z15: 153 (죽천리) | AA15: 58 | AB15: BBB- | AC15: 기타 발전기 및 전기변환장치 제조업 | AD15: 제조업 | AF15: =COUNTIFS($E:$E,E15) -> 1
A16: 경북법인고객담당 | B16: 법인고객영업2부 | C16: 법인고객영업1팀 | D16: 정윤성 | E16: 1-1EYWFXK | F16: 한국수력원자력 포항에너지파크 | G16: 법인가치고객 | H16: 사업장 | I16: 1101112207127 | J16: 2468502431 | K16: 사업장 | L16: 정상 | M16: 에너지 | N16: 에너지/환경 | O16: Public>공공>수도/가스/전기 | P16: 8 | Q16: 판단제외대상 | R16: 주식회사 | S16: 분할신설 | T16: 정상 | U16: 경북 경주시 문무대왕면 | V16: 장항리 1270번지 | W16: 054 704 2114 | X16: 원자력, 수력 발전 | Y16: 경북 경주시 문무대왕면 불국로 | Z16: 1655 (장항리) | AA16: 12806 | AB16: NR | AC16: 원자력 발전업 | AD16: 제조업 | AF16: =COUNTIFS($E:$E,E16) -> 1
A17: 경북법인고객담당 | B17: 법인고객영업2부 | C17: 법인고객영업1팀 | D17: 황성욱 | E17: 0CRMHVAHRCK | F17: 플라스틱옴니엄코리아뉴에너지 주식회사 | G17: 법인가치고객 | H17: 본사 | I17: 1358110399246 | J17: 5188801755 | K17: 본사 | L17: 정상 | O17: Retail/Service>서비스업>사업서비스업>연구소-공학 | P17: 11 | Q17: 소기업 | R17: 주식회사 | S17: 신규설립(개업) | T17: 정상 | U17: 경기 수원시 영통구 이의동 | V17: 906-5번지 경기알앤디비센터 312호, 313호 | W17: 031 888 5221 | X17: 자동차용 기구, 설비, 기계장치 | Y17: 경기 수원시 영통구 광교로 | Z17: 105, 312호, 313호 (이의동,경기알앤디비센터) | AA17: 33 | AB17: BB- | AC17: 그외 기타 자동차 부품 제조업 | AD17: 제조업 | AF17: =COUNTIFS($E:$E,E17) -> 1
A18: 경북법인고객담당 | B18: 법인고객영업1부 | C18: 법인고객영업2팀 | D18: 서유정 | E18: L0000009723 | F18: 풍기특산물영농조합법인 | G18: 법인가치고객 | H18: 본사 | I18: 1756710000083 | J18: 5128104610 | AF18: =COUNTIFS($E:$E,E18) -> 1
A19: 경북법인고객담당 | B19: 법인고객영업1부 | C19: 법인고객영업2팀 | D19: 서유정 | E19: A0001597936 | F19: 풍기인삼협동조합 서울사무소 | G19: 법인가치고객 | H19: 본사 | I19: 1756710001536 | J19: 5128200019 | AF19: =COUNTIFS($E:$E,E19) -> 1
A20: 경북법인고객담당 | B20: 법인고객영업2부 | C20: 법인고객영업2팀 | D20: 이대석 | E20: L0000047770 | F20: 포항축협흥해지소 | G20: 법인가치고객 | H20: 본사 | AF20: =COUNTIFS($E:$E,E20) -> 1
A21: 경북법인고객담당 | B21: 법인고객영업2부 | C21: 법인고객영업2팀 | D21: 이대석 | E21: A0001244134 | F21: 포항중앙교회 | G21: 법인가치고객 | H21: 본사 | AF21: =COUNTIFS($E:$E,E21) -> 1
A22: 경북법인고객담당 | B22: 법인고객영업2부 | C22: 법인고객영업2팀 | D22: 정연오 | E22: A0002770258 | F22: 포항스틸러스 | G22: 법인가치고객 | H22: 본사 | I22: 1746110022050 | J22: 5068119006 | K22: 본사 | L22: 정상 | M22: 서비스 | N22: 공통 | O22: Retail/Service>서비스업>오락/문화 서비스업>프로축구 | P22: 52 | Q22: 중기업 | R22: 주식회사 | S22: 신규설립(개업) | T22: 정상 | U22: 경북 포항시 북구 죽도동 | V22: 614-8번지 동양빌딩 7층 | W22: 054 282 2002 | X22: 프로축구 흥행사업 | Y22: 경북 포항시 북구 중흥로 | Z22: 231, 7층 (죽도동,동양빌딩) | AA22: 17 | AB22: BBB+ | AC22: 그외 기타 스포츠 서비스업 | AD22: 제조업 | AF22: =COUNTIFS($E:$E,E22) -> 1
A23: 경북법인고객담당 | B23: 법인고객영업2부 | C23: 법인고객영업2팀 | D23: 오다영 | E23: 1-NDI8TI | F23: 포스코인재창조원 | G23: 법인가치고객 | K23: 본사 | L23: 정상 | M23: 교육 | N23: 공공 | O23: 교육상담 | P23: 41 | Q23: 대기업 | R23: 주식회사 | S23: 신규설립(개업) | T23: 정상 | U23: 인천 연수구 송도동 | V23: 180-1번지 | W23: 054 240 5685 | X23: 교육서비스 및 직업능력개발훈련사업 | Y23: 인천 연수구 송도과학로 | Z23: 100 (송도동) | AA23: 157 | AB23: A- | AD23: 제조업 | AF23: =COUNTIFS($E:$E,E23) -> 1
A24: 경북법인고객담당 | B24: 법인고객영업2부 | C24: 법인고객영업2팀 | D24: 정연오 | E24: A0001392114 | F24: 티엠테크(주) | G24: 법인가치고객 | H24: 본사 | I24: 1717110080265 | J24: 5068165801 | K24: 본사 | L24: 정상 | M24: 제조업 | N24: 기업 | O24: Manufacture>정유/화학>일반화학>유기질비료제조업 | P24: 1 | Q24: 중기업 | R24: 주식회사 | S24: 신규설립(개업) | T24: 정상 | U24: 경북 포항시 남구 호동 | V24: 611번지 | W24: 054 284 0244 | X24: 일반철물 | Y24: 경북 포항시 남구 서원재로 | Z24: 7 (호동,(주)포스렉) | AA24: 80 | AB24: BBB | AC24: 그외 기타 달리 분류되지 않은 제품 제조업 | AD24: 제조업 | AF24: =COUNTIFS($E:$E,E24) -> 2
A25: 경북법인고객담당 | B25: 법인고객영업2부 | C25: 법인고객영업2팀 | D25: 조영욱 | E25: A0001392114 | F25: 티엠테크(주) | G25: 법인가치고객 | H25: 본사 | I25: 1717110080265 | J25: 5068165801 | K25: 본사 | L25: 정상 | M25: 제조업 | N25: 기업 | O25: Manufacture>정유/화학>일반화학>유기질비료제조업 | P25: 1 | Q25: 중기업 | R25: 주식회사 | S25: 신규설립(개업) | T25: 정상 | U25: 경북 포항시 남구 호동 | V25: 611번지 | W25: 054 284 0244 | X25: 일반철물 | Y25: 경북 포항시 남구 서원재로 | Z25: 7 (호동,(주)포스렉) | AA25: 80 | AB25: BBB | AC25: 그외 기타 달리 분류되지 않은 제품 제조업 | AD25: 제조업 | AF25: =COUNTIFS($E:$E,E25) -> 2
A26: 경북법인고객담당 | B26: 법인고객영업2부 | C26: 법인고객영업1팀 | D26: 정윤성 | E26: L0000035902 | F26: 티에스오토모티브 | G26: 법인가치고객 | H26: 본사 | I26: 1801110058908 | J26: 6108122718 | AF26: =COUNTIFS($E:$E,E26) -> 1
A27: 경북법인고객담당 | B27: 법인고객영업3부 | C27: 법인고객영업2팀 | D27: 권도경 | E27: L0000019264 | F27: 태평양금속(주) | G27: 법인가치고객 | H27: 본사 | I27: 1101110208052 | J27: 5138500333 | AF27: =COUNTIFS($E:$E,E27) -> 1
A28: 경북법인고객담당 | B28: 법인고객영업3부 | C28: 법인고객영업1팀 | D28: 박하림 | E28: A0001281302 | F28: 탑앤양지 | G28: 법인가치고객 | H28: 본사 | I28: 1760110037504 | J28: 5138133516 | K28: 본사 | L28: 정상 | M28: 판매업 | N28: 공통 | O28: Retail/Service>도소매>무역, 중개업>무역업-종합 | P28: 19 | Q28: 한시성중소기업 | R28: 주식회사 | S28: 신규설립(개업) | T28: 정상 | U28: 경북 구미시 황상동 | V28: 500번지 | W28: 054 472 4997 | X28: 차량용 전장부문 | Y28: 경북 구미시 옥계2공단로 | Z28: 46-14 (황상동) | AA28: 214 | AB28: A- | AD28: 제조업 | AF28: =COUNTIFS($E:$E,E28) -> 1
A29: 경북법인고객담당 | B29: 법인고객영업3부 | C29: 법인고객영업2팀 | D29: 신동희 | E29: A0001556033 | F29: 타타대우상용차대구경북판매(주) | G29: 법인가치고객 | H29: 본사 | I29: 1752110031743 | J29: 5138158856 | K29: 본사 | L29: 정상 | M29: 판매업 | N29: 공통 | O29: Retail/Service>도소매>자동차관련 판매>자동차판매-종합 | P29: 39 | Q29: 소기업 | R29: 주식회사 | S29: 신규설립(개업) | T29: 정상 | U29: 경북 칠곡군 왜관읍 | V29: 삼청리 989-1번지 | X29: 자동차, 건설기계 | Y29: 경북 칠곡군 왜관읍 칠곡대로 | Z29: 1921 (삼청리) | AA29: 0 | AB29: BB+ | AC29: 자동차 신품 판매업 | AD29: 제조업 | AF29: =COUNTIFS($E:$E,E29) -> 1
A30: 경북법인고객담당 | B30: 법인고객영업3부 | C30: 법인고객영업2팀 | D30: 권도경 | E30: L0000041760 | F30: 콜렉터신영(주) | G30: 법인가치고객 | H30: 본사 | I30: 1753110000374 | J30: 5138100621 | K30: 본사 | L30: 정상 | M30: 제조업 | N30: 기업 | O30: Manufacture>전자>전기전자장비>전자부품제조 | P30: 17 | Q30: 중기업 | R30: 주식회사 | S30: 신규설립(개업) | T30: 정상 | U30: 경북 구미시 산동읍 | V30: 봉산리 390번지 | W30: 054 470 0600 | X30: 자동차모터 부품인 정류자 외 | Y30: 경북 구미시 산동읍 산호대로45길 | Z30: 24 (봉산리) | AA30: 86 | AB30: BBB+ | AC30: 자동차용 전기장치 제조업 | AD30: 제조업 | AF30: =COUNTIFS($E:$E,E30) -> 1
A31: 경북법인고객담당 | B31: 법인고객영업3부 | C31: 법인고객영업1팀 | D31: 박하림 | E31: A0001215217 | F31: 케이비아이건설(주) | G31: 법인가치고객 | H31: 본사 | I31: 1748110020969 | J31: 5158116513 | K31: 본사 | L31: 정상 | M31: 건설업 | N31: 건설/호텔 | O31: Manufacture>중공업>건설>건설업-종합 | P31: 53 | Q31: 중기업 | R31: 주식회사 | S31: 신규설립(개업) | T31: 정상 | U31: 경북 구미시 임수동 | V31: 92-77번지 | W31: 054 473 1116 | X31: 토목건축공사업(광공업용 건축공사, 항만, 도로공사 외 ) | Y31: 경북 구미시 3공단1로 | Z31: 284 (임수동) | AA31: 78 | AB31: B+ | AC31: 기타 토목시설물 건설업 | AD31: 제조업 | AF31: =COUNTIFS($E:$E,E31) -> 1
A32: 경북법인고객담당 | B32: 법인고객영업3부 | C32: 법인고객영업2팀 | D32: 박종섭 | E32: 0CWKFOZIZER | F32: 케이브이머티리얼즈 주식회사 | G32: 핵심고객 | H32: 본사 | I32: 1760110144169 | J32: 3958102021 | AF32: =COUNTIFS($E:$E,E32) -> 1
A33: 경북법인고객담당 | B33: 법인고객영업2부 | C33: 법인고객영업2팀 | D33: 이대석 | E33: A0001243626 | F33: 청수산업주식회사 | G33: 법인가치고객 | H33: 본사 | I33: 1717110057777 | J33: 5068150915 | K33: 본사 | L33: 정상 | M33: 환경 | N33: 에너지/환경 | O33: Public>보건/복지업>환경 정화>분뇨수거 | P33: 5 | Q33: 중기업 | R33: 주식회사 | S33: 신규설립(개업) | T33: 정상 | U33: 경북 포항시 북구 흥해읍 | V33: 대련리 55번지 | W33: 054 261 7423 | X33: 분뇨처리 및 정화조청소 | Y33: 경북 포항시 북구 흥해읍 새마을로 | Z33: 260 (대련리) | AA33: 38 | AB33: BB- | AC33: 분뇨 처리업 | AD33: 제조업 | AF33: =COUNTIFS($E:$E,E33) -> 2
A34: 경북법인고객담당 | B34: 법인고객영업2부 | C34: 법인고객영업2팀 | D34: 조영욱 | E34: A0001243626 | F34: 청수산업주식회사 | G34: 법인가치고객 | H34: 본사 | I34: 1717110057777 | J34: 5068150915 | K34: 본사 | L34: 정상 | M34: 환경 | N34: 에너지/환경 | O34: Public>보건/복지업>환경 정화>분뇨수거 | P34: 5 | Q34: 중기업 | R34: 주식회사 | S34: 신규설립(개업) | T34: 정상 | U34: 경북 포항시 북구 흥해읍 | V34: 대련리 55번지 | W34: 054 261 7423 | X34: 분뇨처리 및 정화조청소 | Y34: 경북 포항시 북구 흥해읍 새마을로 | Z34: 260 (대련리) | AA34: 38 | AB34: BB- | AC34: 분뇨 처리업 | AD34: 제조업 | AF34: =COUNTIFS($E:$E,E34) -> 2
A35: 경북법인고객담당 | B35: 법인고객영업1부 | C35: 법인고객영업2팀 | D35: 서유정 | E35: 1-I5XPUN | F35: 청량산비나리마을영농조합법인 | G35: 법인가치고객 | H35: 본사 | I35: 1757710002110 | J35: 5128119791 | K35: 본사 | L35: 정상 | M35: 1차산업 | N35: 공통 | O35: Retail/Service>숙박/음식점/부동산/임대업>음식점>음식점-기사식당 | P35: 2 | Q35: 소상공인 | R35: 기타법인 | S35: 신규설립(개업) | T35: 정상 | U35: 경북 봉화군 명호면 | V35: 풍호리 227-7번지 | Y35: 경북 봉화군 명호면 비나리길 | Z35: 141 (풍호리) | AA35: 0 | AC35: 기타 시설작물 재배업 | AD35: 제조업 | AF35: =COUNTIFS($E:$E,E35) -> 1
A36: 경북법인고객담당 | B36: 법인고객영업1부 | C36: 법인고객영업1팀 | D36: 권항구 | E36: L0001763296 | F36: 청기면사무소 | G36: 법인가치고객 | H36: 본사 | J36: 5088302451 | K36: 본사 | L36: 정상 | M36: 지자체/공공 | N36: 공공 | O36: Public>공공>정부/관청>면사무소 | P36: 8 | AA36: 0 | AF36: =COUNTIFS($E:$E,E36) -> 1
A37: 경북법인고객담당 | B37: 법인고객영업1부 | C37: 법인고객영업1팀 | D37: 권항구 | E37: L0001763295 | F37: 진보면사무소 | G37: 법인가치고객 | H37: 본사 | J37: 5088301845 | K37: 본사 | L37: 기타 | M37: 지자체/공공 | N37: 공공 | P37: 9 | AA37: 0 | AF37: =COUNTIFS($E:$E,E37) -> 1
A38: 경북법인고객담당 | B38: 법인고객영업3부 | C38: 법인고객영업1팀 | D38: 김승환 | E38: L0000017310 | F38: 직지농협협동조합 | G38: 핵심고객 | H38: 본사 | I38: 1713360000293 | J38: 5108204213 | K38: 본사 | L38: 정상 | M38: 금융 | N38: 공통 | O38: Finance>금융>금고/조합/리스>금융업-종합금융업 | P38: 13 | R38: 조합 | S38: 신규설립(개업) | T38: 정상 | U38: 경북 김천시 봉산면 | V38: 덕천리 646-3번지 | Y38: 경북 김천시 봉산면 황악로 | Z38: 1736 (덕천리) | AA38: 35 | AC38: 신용조합 | AF38: =COUNTIFS($E:$E,E38) -> 1
A39: 경북법인고객담당 | B39: 법인고객영업3부 | C39: 법인고객영업2팀 | D39: 신동희 | E39: L0000239715 | F39: 지천단위농업협동조합장 | G39: 법인가치고객 | H39: 본사 | I39: 1752360000077 | J39: 5048202748 | K39: 본사 | L39: 정상 | M39: 금융 | N39: 공통 | O39: Finance>금융>은행>농협 | P39: 15 | Q39: 판단제외대상 | R39: 조합 | S39: 신규설립(개업) | T39: 정상 | U39: 경북 칠곡군 지천면 | V39: 신리 408-1번지 | W39: 054 972 4812 | Y39: 경북 칠곡군 지천면 신동로 | Z39: 153 (신리,지천농협) | AA39: 19 | AB39: BBB+ | AC39: 신용조합 | AD39: 제조업 | AF39: =COUNTIFS($E:$E,E39) -> 1
A40: 경북법인고객담당 | B40: 법인고객영업3부 | C40: 법인고객영업1팀 | D40: 박하림 | E40: L0000002539 | F40: 지에이치신소재 | G40: 법인가치고객 | H40: 본사 | I40: 1955110052004 | J40: 6158122009 | K40: 본사 | L40: 정상 | M40: 제조업 | N40: 기업 | O40: Manufacture>정유/화학>석유화학>폴리에틸렌수지(제조) | P40: 5 | Q40: 중견기업 | R40: 주식회사 | S40: 법인전환 | T40: 정상 | U40: 경북 구미시 공단동 | V40: 313-6번지 | W40: 054 460 8100 | X40: 부직포(Floor carpet, ISOdash, Seat back, Trunk mat, Package tray, Engine block외)/ 원사(PP S/F)등 | Y40: 경북 구미시 1공단로4길 | Z40: 141-54 (공단동) | AA40: 132 | AB40: BBB+ | AC40: 부직포 및 펠트 제조업 | AD40: 제조업 | AF40: =COUNTIFS($E:$E,E40) -> 1
A41: 경북법인고객담당 | B41: 법인고객영업3부 | C41: 법인고객영업2팀 | D41: 권도경 | E41: A0002847773 | F41: ㈜씨에스텍 | G41: 법인가치고객 | H41: 본사 | I41: 1701110206939 | J41: 5028160518 | K41: 본사 | L41: 정상 | M41: 건설업 | N41: 건설/호텔 | O41: Manufacture>중공업>건설>건물건설-종합 | P41: 17 | Q41: 중기업 | R41: 주식회사 | S41: 신규설립(개업) | T41: 정상 | U41: 경북 경산시 압량읍 | V41: 신월리 2-18번지 | W41: 053 761 5083 | X41: 태양광발전장치 설치공사, 전기공사 외 | Y41: 경북 경산시 압량읍 해오름길 | Z41: 140-11 (신월리) | AA41: 43 | AB41: CCC+ | AC41: 일반전기 공사업 | AD41: 제조업 | AF41: =COUNTIFS($E:$E,E41) -> 1
A42: 경북법인고객담당 | B42: 법인고객영업1부 | C42: 법인고객영업2팀 | D42: 김병욱 | E42: 0AKVIIQJH5N | F42: 주식회사해피니스 | G42: 법인가치고객 | H42: 본사 | I42: 1756110028544 | J42: 8738803233 | K42: 본사 | L42: 정상 | O42: 건설업-컨테이너하우스 | P42: 2 | Q42: 소기업 | R42: 주식회사 | S42: 신규설립(개업) | T42: 정상 | U42: 경북 영주시 휴천동 | V42: 642-50번지 1층 | Y42: 경북 영주시 선비로 | Z42: 111, 1층 (휴천동) | AA42: 0 | AC42: 고용알선업 | AD42: 제조업 | AF42: =COUNTIFS($E:$E,E42) -> 1
...

Sheet 성장고객
E1: 1 | F1: 2 | G1: 3 | H1: 4 | I1: 5 | J1: 6 | K1: 7 | L1: 8 | M1: 9 | N1: 10 | O1: 11 | P1: 12 | Q1: 13 | R1: 14 | S1: 15 | T1: 16 | U1: 17 | V1: 18 | W1: 19 | X1: 20 | Y1: 21 | Z1: 22 | AA1: 23 | AB1: 24 | AC1: 25 | AD1: 26 | AE1: 27 | AF1: 28 | AG1: 29 | AH1: 30 | AI1: 31 | AJ1: 32 | AK1: 33 | AL1: 34 | AM1: 35 | AN1: 36 | AO1: 37 | AP1: 38 | AQ1: 39 | AR1: 40 | AS1: 41 | AT1: 42 | AU1: 43 | AV1: 44 | AW1: 45 | AX1: 46 | AY1: 47 | AZ1: 48 | BA1: 49 | BB1: 50 | BC1: 51 | BD1: 52 | BE1: 53 | BF1: 54 | BG1: 55 | BH1: 56 | BI1: 57 | BJ1: 58 | BK1: 59 | BL1: 60 | BM1: 61 | BN1: 62 | BO1: 63 | BP1: 64 | BQ1: 65 | BR1: 66 | BS1: 67 | BT1: 68 | BU1: 69 | BV1: 70 | BW1: 71 | BX1: 72 | BY1: 73 | BZ1: 74 | CA1: 75 | CB1: 76 | CC1: 77 | CD1: 78 | CE1: 79 | CF1: 80 | CG1: 81 | CH1: 82 | CI1: 83 | CJ1: 84 | CK1: 85 | CL1: 86 | CM1: 87 | CN1: 88 | CO1: 89 | CP1: 90 | CQ1: 91 | CR1: 92
AO3: 전체매출 | AP3: 전체매출 | AQ3: 전체매출 | AR3: 전체매출 | AS3: 전체매출 | AT3: 전체매출 | AU3: 전체매출 | AV3: 전체매출 | AW3: 전체매출 | AX3: 전체매출 | AY3: 전체매출 | AZ3: 전체매출 | BA3: 전체매출 | BB3: 전체매출 | BC3: 신규매출 | BD3: 신규매출 | BE3: 신규매출 | BF3: 신규매출 | BG3: 신규매출 | BH3: 신규매출 | BI3: 신규매출 | BJ3: 신규매출 | BK3: 신규매출 | BL3: 신규매출 | BM3: 신규매출 | BN3: 신규매출 | BO3: 신규매출 | BP3: 신규매출
A4: 법인단 | B4: 영업부 | C4: 팀 | D4: 영업사원 | E4: 관리고객ID | F4: 관리고객명 | G4: 고객분류 | H4: 계층유형 | I4: 법인등록번호 | J4: 사업자번호 | K4: 계층유형 | L4: 사업상태 | M4: Biz 업종1 | N4: Biz 업종2 | O4: 114업종 | P4: 회선수 | Q4: 기업규모 | R4: 기업형태 | S4: 설립형태 | T4: 기업상태 | U4: 지번주소 | V4: 지번상세주소 | W4: 전화번호 | X4: 제품명 | Y4: 도로명주소 | Z4: 도로명상세주소 | AA4: 근로자수총합 | AB4: 신용등급 | AC4: 신업종명 | AD4: 재무업종명 | AE4: 상품1 | AF4: 회선1 | AG4: 상품2 | AH4: 회선2 | AI4: 상품3 | AJ4: 회선3 | AK4: 상품4 | AL4: 회선4 | AM4: 상품5 | AN4: 회선5 | AO4: '25.1월 | AP4: '25.2월 | AQ4: '25.3월 | AR4: '25.4월 | AS4: '25.5월 | AT4: '25.6월 | AU4: '25.7월 | AV4: '25.8월 | AW4: '25.9월 | AX4: '25.10월 | AY4: '25.11월 | AZ4: '25.12월 | BA4: '25년 월평균 매출 | BB4: '25년 매출합계 | BC4: '25.1월 | BD4: '25.2월 | BE4: '25.3월 | BF4: '25.4월 | BG4: '25.5월 | BH4: '25.6월 | BI4: '25.7월 | BJ4: '25.8월 | BK4: '25.9월 | BL4: '25.10월 | BM4: '25.11월 | BN4: '25.12월 | BO4: '25년 월평균 매출 | BP4: '25년 매출합계 | BQ4: 신규상품1 | BR4: 신규1매출 | BS4: 전체 대비 비중 | BT4: 신규상품2 | BU4: 신규2매출 | BV4: 전체 대비 비중 | BW4: 신규상품3 | BX4: 신규3매출 | BY4: 전체 대비 비중 | BZ4: 신규상품4 | CA4: 신규4매출 | CB4: 전체 대비 비중 | CC4: 신규상품5 | CD4: 신규5매출 | CE4: 전체 대비 비중 | CF4: 신규매출 | CG4: 전체 대비 비중 | CH4: 전체상품1 | CI4: 전체1매출 | CJ4: 전체상품2 | CK4: 전체2매출 | CL4: 전체상품3 | CM4: 전체3매출 | CN4: 전체상품4 | CO4: 전체4매출 | CP4: 전체상품5 | CQ4: 전체5매출 | CR4: 전체매출
A5: 경북법인고객담당 | B5: 법인고객영업2부 | C5: 법인고객영업2팀 | D5: 정연오 | E5: L0000020275 | F5: 흥해농업협동조합 | G5: 법인가치고객 | H5: 본사 | AE5: {=IF(AF5="","",INDEX(전산회선!$E$4:$E$1141,_xlfn.AGGREGATE(15,6,ROW(전산회선!$E$4:$E$1141)-ROW(전산회선!$E$4)+1/((전산회선!$B$4:$B$1141=$E5)*(전산회선!$F$4:$F$1141=AF5)),1)))} -> 홈일반전화 | AF5: =IFERROR(IF(_xlfn.MAXIFS(전산회선!$F$4:$F$1141,전산회선!$B$4:$B$1141,$E5)=0,"",_xlfn.MAXIFS(전산회선!$F$4:$F$1141,전산회선!$B$4:$B$1141,$E5)),"") -> 10 | AG5: {=IF(AH5="","",INDEX(전산회선!$E$4:$E$1141,_xlfn.AGGREGATE(15,6,ROW(전산회선!$E$4:$E$1141)-ROW(전산회선!$E$4)+1/((전산회선!$B$4:$B$1141=$E5)*(전산회선!$F$4:$F$1141=AH5)),1)))} -> GiGA인터넷 | AH5: =IFERROR(IF(_xlfn.MAXIFS(전산회선!$F$4:$F$1141,전산회선!$B$4:$B$1141,$E5,전산회선!$F$4:$F$1141,"<"&AF5)=0,"",_xlfn.MAXIFS(전산회선!$F$4:$F$1141,전산회선!$B$4:$B$1141,$E5,전산회선!$F$4:$F$1141,"<"&AF5)),"") -> 5 | AI5: {=IF(AJ5="","",INDEX(전산회선!$E$4:$E$1141,_xlfn.AGGREGATE(15,6,ROW(전산회선!$E$4:$E$1141)-ROW(전산회선!$E$4)+1/((전산회선!$B$4:$B$1141=$E5)*(전산회선!$F$4:$F$1141=AJ5)),1)))} -> GTS | AJ5: =IFERROR(IF(_xlfn.MAXIFS(전산회선!$F$4:$F$1141,전산회선!$B$4:$B$1141,$E5,전산회선!$F$4:$F$1141,"<"&AH5)=0,"",_xlfn.MAXIFS(전산회선!$F$4:$F$1141,전산회선!$B$4:$B$1141,$E5,전산회선!$F$4:$F$1141,"<"&AH5)),"") -> 1 | AK5: {=IF(AL5="","",INDEX(전산회선!$E$4:$E$1141,_xlfn.AGGREGATE(15,6,ROW(전산회선!$E$4:$E$1141)-ROW(전산회선!$E$4)+1/((전산회선!$B$4:$B$1141=$E5)*(전산회선!$F$4:$F$1141=AL5)),1)))} | AL5: =IFERROR(IF(_xlfn.MAXIFS(전산회선!$F$4:$F$1141,전산회선!$B$4:$B$1141,$E5,전산회선!$F$4:$F$1141,"<"&AJ5)=0,"",_xlfn.MAXIFS(전산회선!$F$4:$F$1141,전산회선!$B$4:$B$1141,$E5,전산회선!$F$4:$F$1141,"<"&AJ5)),"") | AM5: {=IF(AN5="","",INDEX(전산회선!$E$4:$E$1141,_xlfn.AGGREGATE(15,6,ROW(전산회선!$E$4:$E$1141)-ROW(전산회선!$E$4)+1/((전산회선!$B$4:$B$1141=$E5)*(전산회선!$F$4:$F$1141=AN5)),1)))} | AN5: =IFERROR(IF(_xlfn.MAXIFS(전산회선!$F$4:$F$1141,전산회선!$B$4:$B$1141,$E5,전산회선!$F$4:$F$1141,"<"&AL5)=0,"",_xlfn.MAXIFS(전산회선!$F$4:$F$1141,전산회선!$B$4:$B$1141,$E5,전산회선!$F$4:$F$1141,"<"&AL5)),"") | AO5: 684540 | AP5: 690433 | AQ5: 688074 | AR5: 643603 | AS5: 659306 | AT5: 774434 | AU5: 780564 | AV5: 787781 | AW5: 782970 | AX5: 766634 | AY5: 756308 | AZ5: 1116406 | BA5: 760921.08 | BB5: =SUM(AO5:AZ5) -> 9131053 | BC5: 0 | BD5: 0 | BE5: 0 | BF5: -36990 | BG5: -29790 | BH5: 91710 | BI5: 91710 | BJ5: 91710 | BK5: 91710 | BL5: 91710 | BM5: 91710 | BN5: 91710 | BO5: 47932.5 | BP5: 575190 | BQ5: =IFERROR(INDEX(피벗!$BL$5:$CH$5,1,MATCH($BR5,INDEX(피벗!$BL:$CH,MATCH($E5,피벗!$BJ:$BJ,0),0),0)),"") -> IoT | BR5: =IFERROR(LARGE(INDEX(피벗!$BL:$CH,MATCH(성장고객!$E5,피벗!$BJ:$BJ,0),0),1),"") -> 575190 | BS5: =IFERROR(BR5/$BB5,"") -> 0.062992735 | BT5: =IFERROR(INDEX(피벗!$BL$5:$CH$5,1,MATCH($BU5,INDEX(피벗!$BL:$CH,MATCH($E5,피벗!$BJ:$BJ,0),0),0)),"") | BU5: =IFERROR(LARGE(INDEX(피벗!$BL:$CH,MATCH(성장고객!$E5,피벗!$BJ:$BJ,0),0),2),"") | BV5: =IFERROR(BU5/$BB5,"") | BW5: =IFERROR(INDEX(피벗!$BL$5:$CH$5,1,MATCH($BX5,INDEX(피벗!$BL:$CH,MATCH($E5,피벗!$BJ:$BJ,0),0),0)),"") | BX5: =IFERROR(LARGE(INDEX(피벗!$BL:$CH,MATCH(성장고객!$E5,피벗!$BJ:$BJ,0),0),3),"") | BY5: =IFERROR(BX5/$BB5,"") | BZ5: =IFERROR(INDEX(피벗!$BL$5:$CH$5,1,MATCH($CA5,INDEX(피벗!$BL:$CH,MATCH($E5,피벗!$BJ:$BJ,0),0),0)),"") | CA5: =IFERROR(LARGE(INDEX(피벗!$BL:$CH,MATCH(성장고객!$E5,피벗!$BJ:$BJ,0),0),4),"") | CB5: =IFERROR(CA5/$BB5,"") | CC5: =IFERROR(INDEX(피벗!$BL$5:$CH$5,1,MATCH($CD5,INDEX(피벗!$BL:$CH,MATCH($E5,피벗!$BJ:$BJ,0),0),0)),"") | CD5: =IFERROR(LARGE(INDEX(피벗!$BL:$CH,MATCH(성장고객!$E5,피벗!$BJ:$BJ,0),0),5),"") | CE5: =IFERROR(CD5/$BB5,"") | CF5: =IFERROR(INDEX(피벗!$CI:$CI,MATCH($E5,피벗!$BJ:$BJ,0)),"") -> 575190 | CG5: =IFERROR(CF5/$BB5,"") -> 0.062992735 | CH5: =IFERROR(INDEX(피벗!$EZ$5:$GE$5,1,MATCH($CI5,INDEX(피벗!$EZ:$GE,MATCH($E5,피벗!$EY:$EY,0),0),0)),"") -> 홈일반전화 | CI5: =IFERROR(LARGE(INDEX(피벗!$EZ:$GE,MATCH(성장고객!$E5,피벗!$EY:$EY,0),0),1),"") -> 3555174 | CJ5: =IFERROR(INDEX(피벗!$EZ$5:$GE$5,1,MATCH($CK5,INDEX(피벗!$EZ:$GE,MATCH($E5,피벗!$EY:$EY,0),0),0)),"") -> GiGA인터넷 | CK5: =IFERROR(LARGE(INDEX(피벗!$EZ:$GE,MATCH(성장고객!$E5,피벗!$EY:$EY,0),0),2),"") -> 1966310 | CL5: =IFERROR(INDEX(피벗!$EZ$5:$GE$5,1,MATCH($CM5,INDEX(피벗!$EZ:$GE,MATCH($E5,피벗!$EY:$EY,0),0),0)),"") -> 기업메시징 | CM5: =IFERROR(LARGE(INDEX(피벗!$EZ:$GE,MATCH(성장고객!$E5,피벗!$EY:$EY,0),0),3),"") -> 1098000 | CN5: =IFERROR(INDEX(피벗!$EZ$5:$GE$5,1,MATCH($CO5,INDEX(피벗!$EZ:$GE,MATCH($E5,피벗!$EY:$EY,0),0),0)),"") -> 홈지능망 | CO5: =IFERROR(LARGE(INDEX(피벗!$EZ:$GE,MATCH(성장고객!$E5,피벗!$EY:$EY,0),0),4),"") -> 780450 | CP5: =IFERROR(INDEX(피벗!$EZ$5:$GE$5,1,MATCH($CQ5,INDEX(피벗!$EZ:$GE,MATCH($E5,피벗!$EY:$EY,0),0),0)),"") -> MeGA인터넷 | CQ5: =IFERROR(LARGE(INDEX(피벗!$EZ:$GE,MATCH(성장고객!$E5,피벗!$EY:$EY,0),0),5),"") -> 581400 | CR5: =IFERROR(INDEX(피벗!$GF:$GF,MATCH($E5,피벗!$EY:$EY,0)),"") -> 9131053
A6: 경북법인고객담당 | B6: 법인고객영업1부 | C6: 법인고객영업1팀 | D6: 권항구 | E6: L0001763305 | F6: 현서면사무소 | G6: 법인가치고객 | H6: 본사 | J6: 5088301826 | K6: 본사 | L6: 정상 | M6: 지자체/공공 | N6: 공공 | O6: Public>공공>정부/관청>면사무소 | P6: 19 | AA6: 0 | AE6: {=IF(AF6="","",INDEX(전산회선!$E$4:$E$1141,_xlfn.AGGREGATE(15,6,ROW(전산회선!$E$4:$E$1141)-ROW(전산회선!$E$4)+1/((전산회선!$B$4:$B$1141=$E6)*(전산회선!$F$4:$F$1141=AF6)),1)))} -> 홈일반전화 | AF6: =IFERROR(IF(_xlfn.MAXIFS(전산회선!$F$4:$F$1141,전산회선!$B$4:$B$1141,$E6)=0,"",_xlfn.MAXIFS(전산회선!$F$4:$F$1141,전산회선!$B$4:$B$1141,$E6)),"") -> 12 | AG6: {=IF(AH6="","",INDEX(전산회선!$E$4:$E$1141,_xlfn.AGGREGATE(15,6,ROW(전산회선!$E$4:$E$1141)-ROW(전산회선!$E$4)+1/((전산회선!$B$4:$B$1141=$E6)*(전산회선!$F$4:$F$1141=AH6)),1)))} -> 홈인터넷전화 | AH6: =IFERROR(IF(_xlfn.MAXIFS(전산회선!$F$4:$F$1141,전산회선!$B$4:$B$1141,$E6,전산회선!$F$4:$F$1141,"<"&AF6)=0,"",_xlfn.MAXIFS(전산회선!$F$4:$F$1141,전산회선!$B$4:$B$1141,$E6,전산회선!$F$4:$F$1141,"<"&AF6)),"") -> 3 | AI6: {=IF(AJ6="","",INDEX(전산회선!$E$4:$E$1141,_xlfn.AGGREGATE(15,6,ROW(전산회선!$E$4:$E$1141)-ROW(전산회선!$E$4)+1/((전산회선!$B$4:$B$1141=$E6)*(전산회선!$F$4:$F$1141=AJ6)),1)))} -> MeGA인터넷 | AJ6: =IFERROR(IF(_xlfn.MAXIFS(전산회선!$F$4:$F$1141,전산회선!$B$4:$B$1141,$E6,전산회선!$F$4:$F$1141,"<"&AH6)=0,"",_xlfn.MAXIFS(전산회선!$F$4:$F$1141,전산회선!$B$4:$B$1141,$E6,전산회선!$F$4:$F$1141,"<"&AH6)),"") -> 2 | AK6: {=IF(AL6="","",INDEX(전산회선!$E$4:$E$1141,_xlfn.AGGREGATE(15,6,ROW(전산회선!$E$4:$E$1141)-ROW(전산회선!$E$4)+1/((전산회선!$B$4:$B$1141=$E6)*(전산회선!$F$4:$F$1141=AL6)),1)))} -> GTV | AL6: =IFERROR(IF(_xlfn.MAXIFS(전산회선!$F$4:$F$1141,전산회선!$B$4:$B$1141,$E6,전산회선!$F$4:$F$1141,"<"&AJ6)=0,"",_xlfn.MAXIFS(전산회선!$F$4:$F$1141,전산회선!$B$4:$B$1141,$E6,전산회선!$F$4:$F$1141,"<"&AJ6)),"") -> 1 | AM6: {=IF(AN6="","",INDEX(전산회선!$E$4:$E$1141,_xlfn.AGGREGATE(15,6,ROW(전산회선!$E$4:$E$1141)-ROW(전산회선!$E$4)+1/((전산회선!$B$4:$B$1141=$E6)*(전산회선!$F$4:$F$1141=AN6)),1)))} | AN6: =IFERROR(IF(_xlfn.MAXIFS(전산회선!$F$4:$F$1141,전산회선!$B$4:$B$1141,$E6,전산회선!$F$4:$F$1141,"<"&AL6)=0,"",_xlfn.MAXIFS(전산회선!$F$4:$F$1141,전산회선!$B$4:$B$1141,$E6,전산회선!$F$4:$F$1141,"<"&AL6)),"") | AO6: 143535 | AP6: 143927 | AQ6: 142879 | AR6: 141752 | AS6: 142487 | AT6: 143467 | AU6: 142629 | AV6: 143000 | AW6: 144337 | AX6: 144147 | AY6: 143733 | AZ6: 145210 | BA6: 143425.25 | BB6: =SUM(AO6:AZ6) -> 1721103 | BC6: 0 | BD6: 0 | BE6: 0 | BF6: 0 | BG6: 0 | BH6: 0 | BI6: 0 | BJ6: 0 | BK6: 0 | BL6: 0 | BM6: 0 | BN6: 0 | BO6: 0 | BP6: 0 | BQ6: =IFERROR(INDEX(피벗!$BL$5:$CH$5,1,MATCH($BR6,INDEX(피벗!$BL:$CH,MATCH($E6,피벗!$BJ:$BJ,0),0),0)),"") | BR6: =IFERROR(LARGE(INDEX(피벗!$BL:$CH,MATCH(성장고객!$E6,피벗!$BJ:$BJ,0),0),1),"") | BS6: =IFERROR(BR6/$BB6,"") | BT6: =IFERROR(INDEX(피벗!$BL$5:$CH$5,1,MATCH($BU6,INDEX(피벗!$BL:$CH,MATCH($E6,피벗!$BJ:$BJ,0),0),0)),"") | BU6: =IFERROR(LARGE(INDEX(피벗!$BL:$CH,MATCH(성장고객!$E6,피벗!$BJ:$BJ,0),0),2),"") | BV6: =IFERROR(BU6/$BB6,"") | BW6: =IFERROR(INDEX(피벗!$BL$5:$CH$5,1,MATCH($BX6,INDEX(피벗!$BL:$CH,MATCH($E6,피벗!$BJ:$BJ,0),0),0)),"") | BX6: =IFERROR(LARGE(INDEX(피벗!$BL:$CH,MATCH(성장고객!$E6,피벗!$BJ:$BJ,0),0),3),"") | BY6: =IFERROR(BX6/$BB6,"") | BZ6: =IFERROR(INDEX(피벗!$BL$5:$CH$5,1,MATCH($CA6,INDEX(피벗!$BL:$CH,MATCH($E6,피벗!$BJ:$BJ,0),0),0)),"") | CA6: =IFERROR(LARGE(INDEX(피벗!$BL:$CH,MATCH(성장고객!$E6,피벗!$BJ:$BJ,0),0),4),"") | CB6: =IFERROR(CA6/$BB6,"") | CC6: =IFERROR(INDEX(피벗!$BL$5:$CH$5,1,MATCH($CD6,INDEX(피벗!$BL:$CH,MATCH($E6,피벗!$BJ:$BJ,0),0),0)),"") | CD6: =IFERROR(LARGE(INDEX(피벗!$BL:$CH,MATCH(성장고객!$E6,피벗!$BJ:$BJ,0),0),5),"") | CE6: =IFERROR(CD6/$BB6,"") | CF6: =IFERROR(INDEX(피벗!$CI:$CI,MATCH($E6,피벗!$BJ:$BJ,0)),"") | CG6: =IFERROR(CF6/$BB6,"") | CH6: =IFERROR(INDEX(피벗!$EZ$5:$GE$5,1,MATCH($CI6,INDEX(피벗!$EZ:$GE,MATCH($E6,피벗!$EY:$EY,0),0),0)),"") -> 홈일반전화 | CI6: =IFERROR(LARGE(INDEX(피벗!$EZ:$GE,MATCH(성장고객!$E6,피벗!$EY:$EY,0),0),1),"") -> 605167 | CJ6: =IFERROR(INDEX(피벗!$EZ$5:$GE$5,1,MATCH($CK6,INDEX(피벗!$EZ:$GE,MATCH($E6,피벗!$EY:$EY,0),0),0)),"") -> MeGA인터넷 | CK6: =IFERROR(LARGE(INDEX(피벗!$EZ:$GE,MATCH(성장고객!$E6,피벗!$EY:$EY,0),0),2),"") -> 480000 | CL6: =IFERROR(INDEX(피벗!$EZ$5:$GE$5,1,MATCH($CM6,INDEX(피벗!$EZ:$GE,MATCH($E6,피벗!$EY:$EY,0),0),0)),"") -> GiGA인터넷 | CM6: =IFERROR(LARGE(INDEX(피벗!$EZ:$GE,MATCH(성장고객!$E6,피벗!$EY:$EY,0),0),3),"") -> 306000 | CN6: =IFERROR(INDEX(피벗!$EZ$5:$GE$5,1,MATCH($CO6,INDEX(피벗!$EZ:$GE,MATCH($E6,피벗!$EY:$EY,0),0),0)),"") -> GTV | CO6: =IFERROR(LARGE(INDEX(피벗!$EZ:$GE,MATCH(성장고객!$E6,피벗!$EY:$EY,0),0),4),"") -> 120000 | CP6: =IFERROR(INDEX(피벗!$EZ$5:$GE$5,1,MATCH($CQ6,INDEX(피벗!$EZ:$GE,MATCH($E6,피벗!$EY:$EY,0),0),0)),"") -> 홈지능망 | CQ6: =IFERROR(LARGE(INDEX(피벗!$EZ:$GE,MATCH(성장고객!$E6,피벗!$EY:$EY,0),0),5),"") -> 93280 | CR6: =IFERROR(INDEX(피벗!$GF:$GF,MATCH($E6,피벗!$EY:$EY,0)),"") -> 1721103
A7: 경북법인고객담당 | B7: 법인고객영업1부 | C7: 법인고객영업1팀 | D7: 권항구 | E7: L0000223181 | F7: 현서농업협동조합 | G7: 법인가치고객 | H7: 본사 | I7: 1744360000123 | J7: 5088200586 | K7: 본사 | L7: 정상 | M7: 금융 | N7: 공통 | O7: Retail/Service>도소매>자동차관련 판매>주유소 | P7: 22 | Q7: 판단제외대상 | R7: 조합 | S7: 신규설립(개업) | T7: 정상 | U7: 경북 청송군 현서면 | V7: 구산리 100-6번지 | Y7: 경북 청송군 현서면 구산북로 | Z7: 63 (구산리,농협하나로마트) | AA7: 26 | AC7: 산업 단체 | AE7: {=IF(AF7="","",INDEX(전산회선!$E$4:$E$1141,_xlfn.AGGREGATE(15,6,ROW(전산회선!$E$4:$E$1141)-ROW(전산회선!$E$4)+1/((전산회선!$B$4:$B$1141=$E7)*(전산회선!$F$4:$F$1141=AF7)),1)))} -> 홈일반전화 | AF7: =IFERROR(IF(_xlfn.MAXIFS(전산회선!$F$4:$F$1141,전산회선!$B$4:$B$1141,$E7)=0,"",_xlfn.MAXIFS(전산회선!$F$4:$F$1141,전산회선!$B$4:$B$1141,$E7)),"") -> 16 | AG7: {=IF(AH7="","",INDEX(전산회선!$E$4:$E$1141,_xlfn.AGGREGATE(15,6,ROW(전산회선!$E$4:$E$1141)-ROW(전산회선!$E$4)+1/((전산회선!$B$4:$B$1141=$E7)*(전산회선!$F$4:$F$1141=AH7)),1)))} -> 기업인터넷전화 | AH7: =IFERROR(IF(_xlfn.MAXIFS(전산회선!$F$4:$F$1141,전산회선!$B$4:$B$1141,$E7,전산회선!$F$4:$F$1141,"<"&AF7)=0,"",_xlfn.MAXIFS(전산회선!$F$4:$F$1141,전산회선!$B$4:$B$1141,$E7,전산회선!$F$4:$F$1141,"<"&AF7)),"") -> 4 | AI7: {=IF(AJ7="","",INDEX(전산회선!$E$4:$E$1141,_xlfn.AGGREGATE(15,6,ROW(전산회선!$E$4:$E$1141)-ROW(전산회선!$E$4)+1/((전산회선!$B$4:$B$1141=$E7)*(전산회선!$F$4:$F$1141=AJ7)),1)))} -> MeGA인터넷 | AJ7: =IFERROR(IF(_xlfn.MAXIFS(전산회선!$F$4:$F$1141,전산회선!$B$4:$B$1141,$E7,전산회선!$F$4:$F$1141,"<"&AH7)=0,"",_xlfn.MAXIFS(전산회선!$F$4:$F$1141,전산회선!$B$4:$B$1141,$E7,전산회선!$F$4:$F$1141,"<"&AH7)),"") -> 2 | AK7: {=IF(AL7="","",INDEX(전산회선!$E$4:$E$1141,_xlfn.AGGREGATE(15,6,ROW(전산회선!$E$4:$E$1141)-ROW(전산회선!$E$4)+1/((전산회선!$B$4:$B$1141=$E7)*(전산회선!$F$4:$F$1141=AL7)),1)))} | AL7: =IFERROR(IF(_xlfn.MAXIFS(전산회선!$F$4:$F$1141,전산회선!$B$4:$B$1141,$E7,전산회선!$F$4:$F$1141,"<"&AJ7)=0,"",_xlfn.MAXIFS(전산회선!$F$4:$F$1141,전산회선!$B$4:$B$1141,$E7,전산회선!$F$4:$F$1141,"<"&AJ7)),"") | AM7: {=IF(AN7="","",INDEX(전산회선!$E$4:$E$1141,_xlfn.AGGREGATE(15,6,ROW(전산회선!$E$4:$E$1141)-ROW(전산회선!$E$4)+1/((전산회선!$B$4:$B$1141=$E7)*(전산회선!$F$4:$F$1141=AN7)),1)))} | AN7: =IFERROR(IF(_xlfn.MAXIFS(전산회선!$F$4:$F$1141,전산회선!$B$4:$B$1141,$E7,전산회선!$F$4:$F$1141,"<"&AL7)=0,"",_xlfn.MAXIFS(전산회선!$F$4:$F$1141,전산회선!$B$4:$B$1141,$E7,전산회선!$F$4:$F$1141,"<"&AL7)),"") | AO7: 201409 | AP7: 203623 | AQ7: 205937 | AR7: 214853 | AS7: 190451 | AT7: 190357 | AU7: 195159 | AV7: 188825 | AW7: 240281 | AX7: 202189 | AY7: 202617 | AZ7: 205454 | BA7: 203429.58 | BB7: =SUM(AO7:AZ7) -> 2441155 | BC7: 0 | BD7: 0 | BE7: 0 | BF7: 0 | BG7: 0 | BH7: 0 | BI7: 0 | BJ7: 0 | BK7: 43517 | BL7: 11560 | BM7: 11560 | BN7: 12073 | BO7: 6559.1667 | BP7: 78710 | BQ7: =IFERROR(INDEX(피벗!$BL$5:$CH$5,1,MATCH($BR7,INDEX(피벗!$BL:$CH,MATCH($E7,피벗!$BJ:$BJ,0),0),0)),"") -> 홈일반전화 | BR7: =IFERROR(LARGE(INDEX(피벗!$BL:$CH,MATCH(성장고객!$E7,피벗!$BJ:$BJ,0),0),1),"") -> 63920.47 | BS7: =IFERROR(BR7/$BB7,"") -> 0.026184519 | BT7: =IFERROR(INDEX(피벗!$BL$5:$CH$5,1,MATCH($BU7,INDEX(피벗!$BL:$CH,MATCH($E7,피벗!$BJ:$BJ,0),0),0)),"") -> 홈지능망 | BU7: =IFERROR(LARGE(INDEX(피벗!$BL:$CH,MATCH(성장고객!$E7,피벗!$BJ:$BJ,0),0),2),"") -> 14789.53 | BV7: =IFERROR(BU7/$BB7,"") -> 0.006058415 | BW7: =IFERROR(INDEX(피벗!$BL$5:$CH$5,1,MATCH($BX7,INDEX(피벗!$BL:$CH,MATCH($E7,피벗!$BJ:$BJ,0),0),0)),"") -> AI기업지능망 | BX7: =IFERROR(LARGE(INDEX(피벗!$BL:$CH,MATCH(성장고객!$E7,피벗!$BJ:$BJ,0),0),3),"") -> 0 | BY7: =IFERROR(BX7/$BB7,"") -> 0 | BZ7: =IFERROR(INDEX(피벗!$BL$5:$CH$5,1,MATCH($CA7,INDEX(피벗!$BL:$CH,MATCH($E7,피벗!$BJ:$BJ,0),0),0)),"") | CA7: =IFERROR(LARGE(INDEX(피벗!$BL:$CH,MATCH(성장고객!$E7,피벗!$BJ:$BJ,0),0),4),"") | CB7: =IFERROR(CA7/$BB7,"") | CC7: =IFERROR(INDEX(피벗!$BL$5:$CH$5,1,MATCH($CD7,INDEX(피벗!$BL:$CH,MATCH($E7,피벗!$BJ:$BJ,0),0),0)),"") | CD7: =IFERROR(LARGE(INDEX(피벗!$BL:$CH,MATCH(성장고객!$E7,피벗!$BJ:$BJ,0),0),5),"") | CE7: =IFERROR(CD7/$BB7,"") | CF7: =IFERROR(INDEX(피벗!$CI:$CI,MATCH($E7,피벗!$BJ:$BJ,0)),"") -> 78710 | CG7: =IFERROR(CF7/$BB7,"") -> 0.032242934 | CH7: =IFERROR(INDEX(피벗!$EZ$5:$GE$5,1,MATCH($CI7,INDEX(피벗!$EZ:$GE,MATCH($E7,피벗!$EY:$EY,0),0),0)),"") -> 홈일반전화 | CI7: =IFERROR(LARGE(INDEX(피벗!$EZ:$GE,MATCH(성장고객!$E7,피벗!$EY:$EY,0),0),1),"") -> 1073602.5 | CJ7: =IFERROR(INDEX(피벗!$EZ$5:$GE$5,1,MATCH($CK7,INDEX(피벗!$EZ:$GE,MATCH($E7,피벗!$EY:$EY,0),0),0)),"") -> MeGA인터넷 | CK7: =IFERROR(LARGE(INDEX(피벗!$EZ:$GE,MATCH(성장고객!$E7,피벗!$EY:$EY,0),0),2),"") -> 484420 | CL7: =IFERROR(INDEX(피벗!$EZ$5:$GE$5,1,MATCH($CM7,INDEX(피벗!$EZ:$GE,MATCH($E7,피벗!$EY:$EY,0),0),0)),"") -> 홈지능망 | CM7: =IFERROR(LARGE(INDEX(피벗!$EZ:$GE,MATCH(성장고객!$E7,피벗!$EY:$EY,0),0),3),"") -> 296789.53 | CN7: =IFERROR(INDEX(피벗!$EZ$5:$GE$5,1,MATCH($CO7,INDEX(피벗!$EZ:$GE,MATCH($E7,피벗!$EY:$EY,0),0),0)),"") -> 기업인터넷전화 | CO7: =IFERROR(LARGE(INDEX(피벗!$EZ:$GE,MATCH(성장고객!$E7,피벗!$EY:$EY,0),0),4),"") -> 281669 | CP7: =IFERROR(INDEX(피벗!$EZ$5:$GE$5,1,MATCH($CQ7,INDEX(피벗!$EZ:$GE,MATCH($E7,피벗!$EY:$EY,0),0),0)),"") -> 기업메시징 | CQ7: =IFERROR(LARGE(INDEX(피벗!$EZ:$GE,MATCH(성장고객!$E7,피벗!$EY:$EY,0),0),5),"") -> 256650 | CR7: =IFERROR(INDEX(피벗!$GF:$GF,MATCH($E7,피벗!$EY:$EY,0)),"") -> 2441155
A8: 경북법인고객담당 | B8: 법인고객영업2부 | C8: 법인고객영업2팀 | D8: 오다영 | E8: 0D99FI5JM5G | F8: 현대피엔에스(주) | G8: 법인가치고객 | H8: 본사 | K8: 본사 | L8: 정상 | M8: 제조업 | N8: 기업 | P8: 1 | Q8: 중견기업 | R8: 주식회사 | S8: 신규설립(개업) | T8: 정상 | U8: 서울 강남구 삼성1동 | V8: 157-37번지 위워크빌딩 16층 | Y8: 서울 강남구 테헤란로 | Z8: 507, 16층 (삼성동,위워크빌딩) | AA8: 45 | AB8: A- | AC8: 그외 기타 일반목적용 기계 제조업 | AD8: 제조업 | AE8: {=IF(AF8="","",INDEX(전산회선!$E$4:$E$1141,_xlfn.AGGREGATE(15,6,ROW(전산회선!$E$4:$E$1141)-ROW(전산회선!$E$4)+1/((전산회선!$B$4:$B$1141=$E8)*(전산회선!$F$4:$F$1141=AF8)),1)))} | AF8: =IFERROR(IF(_xlfn.MAXIFS(전산회선!$F$4:$F$1141,전산회선!$B$4:$B$1141,$E8)=0,"",_xlfn.MAXIFS(전산회선!$F$4:$F$1141,전산회선!$B$4:$B$1141,$E8)),"") | AG8: {=IF(AH8="","",INDEX(전산회선!$E$4:$E$1141,_xlfn.AGGREGATE(15,6,ROW(전산회선!$E$4:$E$1141)-ROW(전산회선!$E$4)+1/((전산회선!$B$4:$B$1141=$E8)*(전산회선!$F$4:$F$1141=AH8)),1)))} | AH8: =IFERROR(IF(_xlfn.MAXIFS(전산회선!$F$4:$F$1141,전산회선!$B$4:$B$1141,$E8,전산회선!$F$4:$F$1141,"<"&AF8)=0,"",_xlfn.MAXIFS(전산회선!$F$4:$F$1141,전산회선!$B$4:$B$1141,$E8,전산회선!$F$4:$F$1141,"<"&AF8)),"") | AI8: {=IF(AJ8="","",INDEX(전산회선!$E$4:$E$1141,_xlfn.AGGREGATE(15,6,ROW(전산회선!$E$4:$E$1141)-ROW(전산회선!$E$4)+1/((전산회선!$B$4:$B$1141=$E8)*(전산회선!$F$4:$F$1141=AJ8)),1)))} | AJ8: =IFERROR(IF(_xlfn.MAXIFS(전산회선!$F$4:$F$1141,전산회선!$B$4:$B$1141,$E8,전산회선!$F$4:$F$1141,"<"&AH8)=0,"",_xlfn.MAXIFS(전산회선!$F$4:$F$1141,전산회선!$B$4:$B$1141,$E8,전산회선!$F$4:$F$1141,"<"&AH8)),"") | AK8: {=IF(AL8="","",INDEX(전산회선!$E$4:$E$1141,_xlfn.AGGREGATE(15,6,ROW(전산회선!$E$4:$E$1141)-ROW(전산회선!$E$4)+1/((전산회선!$B$4:$B$1141=$E8)*(전산회선!$F$4:$F$1141=AL8)),1)))} | AL8: =IFERROR(IF(_xlfn.MAXIFS(전산회선!$F$4:$F$1141,전산회선!$B$4:$B$1141,$E8,전산회선!$F$4:$F$1141,"<"&AJ8)=0,"",_xlfn.MAXIFS(전산회선!$F$4:$F$1141,전산회선!$B$4:$B$1141,$E8,전산회선!$F$4:$F$1141,"<"&AJ8)),"") | AM8: {=IF(AN8="","",INDEX(전산회선!$E$4:$E$1141,_xlfn.AGGREGATE(15,6,ROW(전산회선!$E$4:$E$1141)-ROW(전산회선!$E$4)+1/((전산회선!$B$4:$B$1141=$E8)*(전산회선!$F$4:$F$1141=AN8)),1)))} | AN8: =IFERROR(IF(_xlfn.MAXIFS(전산회선!$F$4:$F$1141,전산회선!$B$4:$B$1141,$E8,전산회선!$F$4:$F$1141,"<"&AL8)=0,"",_xlfn.MAXIFS(전산회선!$F$4:$F$1141,전산회선!$B$4:$B$1141,$E8,전산회선!$F$4:$F$1141,"<"&AL8)),"") | AO8: 5830 | AP8: 5830 | AQ8: 5830 | AR8: 5830 | AS8: 5830 | AT8: 5830 | AU8: 5830 | AV8: 7030 | AW8: 7030 | AX8: 7030 | AY8: 0 | AZ8: 0 | BA8: 5158.3333 | BB8: =SUM(AO8:AZ8) -> 61900 | BC8: 0 | BD8: 0 | BE8: 0 | BF8: 0 | BG8: 0 | BH8: 0 | BI8: 0 | BJ8: 0 | BK8: 0 | BL8: 0 | BM8: 0 | BN8: 0 | BO8: 0 | BP8: 0 | BQ8: =IFERROR(INDEX(피벗!$BL$5:$CH$5,1,MATCH($BR8,INDEX(피벗!$BL:$CH,MATCH($E8,피벗!$BJ:$BJ,0),0),0)),"") | BR8: =IFERROR(LARGE(INDEX(피벗!$BL:$CH,MATCH(성장고객!$E8,피벗!$BJ:$BJ,0),0),1),"") | BS8: =IFERROR(BR8/$BB8,"") | BT8: =IFERROR(INDEX(피벗!$BL$5:$CH$5,1,MATCH($BU8,INDEX(피벗!$BL:$CH,MATCH($E8,피벗!$BJ:$BJ,0),0),0)),"") | BU8: =IFERROR(LARGE(INDEX(피벗!$BL:$CH,MATCH(성장고객!$E8,피벗!$BJ:$BJ,0),0),2),"") | BV8: =IFERROR(BU8/$BB8,"") | BW8: =IFERROR(INDEX(피벗!$BL$5:$CH$5,1,MATCH($BX8,INDEX(피벗!$BL:$CH,MATCH($E8,피벗!$BJ:$BJ,0),0),0)),"") | BX8: =IFERROR(LARGE(INDEX(피벗!$BL:$CH,MATCH(성장고객!$E8,피벗!$BJ:$BJ,0),0),3),"") | BY8: =IFERROR(BX8/$BB8,"") | BZ8: =IFERROR(INDEX(피벗!$BL$5:$CH$5,1,MATCH($CA8,INDEX(피벗!$BL:$CH,MATCH($E8,피벗!$BJ:$BJ,0),0),0)),"") | CA8: =IFERROR(LARGE(INDEX(피벗!$BL:$CH,MATCH(성장고객!$E8,피벗!$BJ:$BJ,0),0),4),"") | CB8: =IFERROR(CA8/$BB8,"") | CC8: =IFERROR(INDEX(피벗!$BL$5:$CH$5,1,MATCH($CD8,INDEX(피벗!$BL:$CH,MATCH($E8,피벗!$BJ:$BJ,0),0),0)),"") | CD8: =IFERROR(LARGE(INDEX(피벗!$BL:$CH,MATCH(성장고객!$E8,피벗!$BJ:$BJ,0),0),5),"") | CE8: =IFERROR(CD8/$BB8,"") | CF8: =IFERROR(INDEX(피벗!$CI:$CI,MATCH($E8,피벗!$BJ:$BJ,0)),"") | CG8: =IFERROR(CF8/$BB8,"") | CH8: =IFERROR(INDEX(피벗!$EZ$5:$GE$5,1,MATCH($CI8,INDEX(피벗!$EZ:$GE,MATCH($E8,피벗!$EY:$EY,0),0),0)),"") -> 기업메시징 | CI8: =IFERROR(LARGE(INDEX(피벗!$EZ:$GE,MATCH(성장고객!$E8,피벗!$EY:$EY,0),0),1),"") -> 61900 | CJ8: =IFERROR(INDEX(피벗!$EZ$5:$GE$5,1,MATCH($CK8,INDEX(피벗!$EZ:$GE,MATCH($E8,피벗!$EY:$EY,0),0),0)),"") | CK8: =IFERROR(LARGE(INDEX(피벗!$EZ:$GE,MATCH(성장고객!$E8,피벗!$EY:$EY,0),0),2),"") | CL8: =IFERROR(INDEX(피벗!$EZ$5:$GE$5,1,MATCH($CM8,INDEX(피벗!$EZ:$GE,MATCH($E8,피벗!$EY:$EY,0),0),0)),"") | CM8: =IFERROR(LARGE(INDEX(피벗!$EZ:$GE,MATCH(성장고객!$E8,피벗!$EY:$EY,0),0),3),"") | CN8: =IFERROR(INDEX(피벗!$EZ$5:$GE$5,1,MATCH($CO8,INDEX(피벗!$EZ:$GE,MATCH($E8,피벗!$EY:$EY,0),0),0)),"") | CO8: =IFERROR(LARGE(INDEX(피벗!$EZ:$GE,MATCH(성장고객!$E8,피벗!$EY:$EY,0),0),4),"") | CP8: =IFERROR(INDEX(피벗!$EZ$5:$GE$5,1,MATCH($CQ8,INDEX(피벗!$EZ:$GE,MATCH($E8,피벗!$EY:$EY,0),0),0)),"") | CQ8: =IFERROR(LARGE(INDEX(피벗!$EZ:$GE,MATCH(성장고객!$E8,피벗!$EY:$EY,0),0),5),"") | CR8: =IFERROR(INDEX(피벗!$GF:$GF,MATCH($E8,피벗!$EY:$EY,0)),"") -> 61900
A9: 경북법인고객담당 | B9: 법인고객영업3부 | C9: 법인고객영업1팀 | D9: 황현철 | E9: L0000025091 | F9: 해평단위농업협동조합 | G9: 핵심고객 | H9: 본사 | I9: 1753360000116 | J9: 5138206374 | K9: 본사 | L9: 정상 | M9: 금융 | N9: 공통 | O9: Finance>금융>은행>농협 | P9: 1 | Q9: 판단제외대상 | R9: 조합 | S9: 신규설립(개업) | T9: 정상 | U9: 경북 구미시 해평면 | V9: 낙성리 58-3번지 | W9: 054 474 4205 | X9: 농협, 금융, 도매 | Y9: 경북 구미시 해평면 해평시장1길 | Z9: 6 (낙성리) | AA9: 45 | AB9: BBB- | AC9: 신용조합 | AD9: 제조업 | AE9: {=IF(AF9="","",INDEX(전산회선!$E$4:$E$1141,_xlfn.AGGREGATE(15,6,ROW(전산회선!$E$4:$E$1141)-ROW(전산회선!$E$4)+1/((전산회선!$B$4:$B$1141=$E9)*(전산회선!$F$4:$F$1141=AF9)),1)))} -> MeGA인터넷 | AF9: =IFERROR(IF(_xlfn.MAXIFS(전산회선!$F$4:$F$1141,전산회선!$B$4:$B$1141,$E9)=0,"",_xlfn.MAXIFS(전산회선!$F$4:$F$1141,전산회선!$B$4:$B$1141,$E9)),"") -> 1 | AG9: {=IF(AH9="","",INDEX(전산회선!$E$4:$E$1141,_xlfn.AGGREGATE(15,6,ROW(전산회선!$E$4:$E$1141)-ROW(전산회선!$E$4)+1/((전산회선!$B$4:$B$1141=$E9)*(전산회선!$F$4:$F$1141=AH9)),1)))} | AH9: =IFERROR(IF(_xlfn.MAXIFS(전산회선!$F$4:$F$1141,전산회선!$B$4:$B$1141,$E9,전산회선!$F$4:$F$1141,"<"&AF9)=0,"",_xlfn.MAXIFS(전산회선!$F$4:$F$1141,전산회선!$B$4:$B$1141,$E9,전산회선!$F$4:$F$1141,"<"&AF9)),"") | AI9: {=IF(AJ9="","",INDEX(전산회선!$E$4:$E$1141,_xlfn.AGGREGATE(15,6,ROW(전산회선!$E$4:$E$1141)-ROW(전산회선!$E$4)+1/((전산회선!$B$4:$B$1141=$E9)*(전산회선!$F$4:$F$1141=AJ9)),1)))} | AJ9: =IFERROR(IF(_xlfn.MAXIFS(전산회선!$F$4:$F$1141,전산회선!$B$4:$B$1141,$E9,전산회선!$F$4:$F$1141,"<"&AH9)=0,"",_xlfn.MAXIFS(전산회선!$F$4:$F$1141,전산회선!$B$4:$B$1141,$E9,전산회선!$F$4:$F$1141,"<"&AH9)),"") | AK9: {=IF(AL9="","",INDEX(전산회선!$E$4:$E$1141,_xlfn.AGGREGATE(15,6,ROW(전산회선!$E$4:$E$1141)-ROW(전산회선!$E$4)+1/((전산회선!$B$4:$B$1141=$E9)*(전산회선!$F$4:$F$1141=AL9)),1)))} | AL9: =IFERROR(IF(_xlfn.MAXIFS(전산회선!$F$4:$F$1141,전산회선!$B$4:$B$1141,$E9,전산회선!$F$4:$F$1141,"<"&AJ9)=0,"",_xlfn.MAXIFS(전산회선!$F$4:$F$1141,전산회선!$B$4:$B$1141,$E9,전산회선!$F$4:$F$1141,"<"&AJ9)),"") | AM9: {=IF(AN9="","",INDEX(전산회선!$E$4:$E$1141,_xlfn.AGGREGATE(15,6,ROW(전산회선!$E$4:$E$1141)-ROW(전산회선!$E$4)+1/((전산회선!$B$4:$B$1141=$E9)*(전산회선!$F$4:$F$1141=AN9)),1)))} | AN9: =IFERROR(IF(_xlfn.MAXIFS(전산회선!$F$4:$F$1141,전산회선!$B$4:$B$1141,$E9,전산회선!$F$4:$F$1141,"<"&AL9)=0,"",_xlfn.MAXIFS(전산회선!$F$4:$F$1141,전산회선!$B$4:$B$1141,$E9,전산회선!$F$4:$F$1141,"<"&AL9)),"") | AO9: 20962 | AP9: 20962 | AQ9: 20962 | AR9: 20962 | AS9: 20962 | AT9: 20962 | AU9: 20962 | AV9: 20962 | AW9: 20962 | AX9: 20962 | AY9: 20962 | AZ9: 20962 | BA9: 20962 | BB9: =SUM(AO9:AZ9) -> 251544 | BC9: 0 | BD9: 0 | BE9: 0 | BF9: 0 | BG9: 0 | BH9: 0 | BI9: 0 | BJ9: 0 | BK9: 0 | BL9: 0 | BM9: 0 | BN9: 0 | BO9: 0 | BP9: 0 | BQ9: =IFERROR(INDEX(피벗!$BL$5:$CH$5,1,MATCH($BR9,INDEX(피벗!$BL:$CH,MATCH($E9,피벗!$BJ:$BJ,0),0),0)),"") | BR9: =IFERROR(LARGE(INDEX(피벗!$BL:$CH,MATCH(성장고객!$E9,피벗!$BJ:$BJ,0),0),1),"") | BS9: =IFERROR(BR9/$BB9,"") | BT9: =IFERROR(INDEX(피벗!$BL$5:$CH$5,1,MATCH($BU9,INDEX(피벗!$BL:$CH,MATCH($E9,피벗!$BJ:$BJ,0),0),0)),"") | BU9: =IFERROR(LARGE(INDEX(피벗!$BL:$CH,MATCH(성장고객!$E9,피벗!$BJ:$BJ,0),0),2),"") | BV9: =IFERROR(BU9/$BB9,"") | BW9: =IFERROR(INDEX(피벗!$BL$5:$CH$5,1,MATCH($BX9,INDEX(피벗!$BL:$CH,MATCH($E9,피벗!$BJ:$BJ,0),0),0)),"") | BX9: =IFERROR(LARGE(INDEX(피벗!$BL:$CH,MATCH(성장고객!$E9,피벗!$BJ:$BJ,0),0),3),"") | BY9: =IFERROR(BX9/$BB9,"") | BZ9: =IFERROR(INDEX(피벗!$BL$5:$CH$5,1,MATCH($CA9,INDEX(피벗!$BL:$CH,MATCH($E9,피벗!$BJ:$BJ,0),0),0)),"") | CA9: =IFERROR(LARGE(INDEX(피벗!$BL:$CH,MATCH(성장고객!$E9,피벗!$BJ:$BJ,0),0),4),"") | CB9: =IFERROR(CA9/$BB9,"") | CC9: =IFERROR(INDEX(피벗!$BL$5:$CH$5,1,MATCH($CD9,INDEX(피벗!$BL:$CH,MATCH($E9,피벗!$BJ:$BJ,0),0),0)),"") | CD9: =IFERROR(LARGE(INDEX(피벗!$BL:$CH,MATCH(성장고객!$E9,피벗!$BJ:$BJ,0),0),5),"") | CE9: =IFERROR(CD9/$BB9,"") | CF9: =IFERROR(INDEX(피벗!$CI:$CI,MATCH($E9,피벗!$BJ:$BJ,0)),"") | CG9: =IFERROR(CF9/$BB9,"") | CH9: =IFERROR(INDEX(피벗!$EZ$5:$GE$5,1,MATCH($CI9,INDEX(피벗!$EZ:$GE,MATCH($E9,피벗!$EY:$EY,0),0),0)),"") -> MeGA인터넷 | CI9: =IFERROR(LARGE(INDEX(피벗!$EZ:$GE,MATCH(성장고객!$E9,피벗!$EY:$EY,0),0),1),"") -> 251544 | CJ9: =IFERROR(INDEX(피벗!$EZ$5:$GE$5,1,MATCH($CK9,INDEX(피벗!$EZ:$GE,MATCH($E9,피벗!$EY:$EY,0),0),0)),"") | CK9: =IFERROR(LARGE(INDEX(피벗!$EZ:$GE,MATCH(성장고객!$E9,피벗!$EY:$EY,0),0),2),"") | CL9: =IFERROR(INDEX(피벗!$EZ$5:$GE$5,1,MATCH($CM9,INDEX(피벗!$EZ:$GE,MATCH($E9,피벗!$EY:$EY,0),0),0)),"") | CM9: =IFERROR(LARGE(INDEX(피벗!$EZ:$GE,MATCH(성장고객!$E9,피벗!$EY:$EY,0),0),3),"") | CN9: =IFERROR(INDEX(피벗!$EZ$5:$GE$5,1,MATCH($CO9,INDEX(피벗!$EZ:$GE,MATCH($E9,피벗!$EY:$EY,0),0),0)),"") | CO9: =IFERROR(LARGE(INDEX(피벗!$EZ:$GE,MATCH(성장고객!$E9,피벗!$EY:$EY,0),0),4),"") | CP9: =IFERROR(INDEX(피벗!$EZ$5:$GE$5,1,MATCH($CQ9,INDEX(피벗!$EZ:$GE,MATCH($E9,피벗!$EY:$EY,0),0),0)),"") | CQ9: =IFERROR(LARGE(INDEX(피벗!$EZ:$GE,MATCH(성장고객!$E9,피벗!$EY:$EY,0),0),5),"") | CR9: =IFERROR(INDEX(피벗!$GF:$GF,MATCH($E9,피벗!$EY:$EY,0)),"") -> 251544
A10: 경북법인고객담당 | B10: 법인고객영업3부 | C10: 법인고객영업2팀 | D10: 박종섭 | E10: L0000010808 | F10: 한보전설주식회사 | G10: 핵심고객 | H10: 본사 | I10: 1760110027761 | J10: 5138124583 | K10: 사업장 | L10: 정상 | M10: 건설업 | N10: 건설/호텔 | O10: Manufacture>중공업>건설>건물건설-종합 | P10: 22 | Q10: 중기업 | R10: 주식회사 | S10: 신규설립(개업) | T10: 정상 | U10: 경북 구미시 임은동 | V10: 666-2번지 | W10: 051 461 0799 | X10: 전기공사, 소방공사, 정보통신공사 | Y10: 경북 구미시 임은길 | Z10: 55-15 (임은동) | AA10: 24 | AB10: BBB- | AC10: 일반전기 공사업 | AD10: 제조업 | AE10: {=IF(AF10="","",INDEX(전산회선!$E$4:$E$1141,_xlfn.AGGREGATE(15,6,ROW(전산회선!$E$4:$E$1141)-ROW(전산회선!$E$4)+1/((전산회선!$B$4:$B$1141=$E10)*(전산회선!$F$4:$F$1141=AF10)),1)))} -> GiGA인터넷 | AF10: =IFERROR(IF(_xlfn.MAXIFS(전산회선!$F$4:$F$1141,전산회선!$B$4:$B$1141,$E10)=0,"",_xlfn.MAXIFS(전산회선!$F$4:$F$1141,전산회선!$B$4:$B$1141,$E10)),"") -> 4 | AG10: {=IF(AH10="","",INDEX(전산회선!$E$4:$E$1141,_xlfn.AGGREGATE(15,6,ROW(전산회선!$E$4:$E$1141)-ROW(전산회선!$E$4)+1/((전산회선!$B$4:$B$1141=$E10)*(전산회선!$F$4:$F$1141=AH10)),1)))} -> GTV | AH10: =IFERROR(IF(_xlfn.MAXIFS(전산회선!$F$4:$F$1141,전산회선!$B$4:$B$1141,$E10,전산회선!$F$4:$F$1141,"<"&AF10)=0,"",_xlfn.MAXIFS(전산회선!$F$4:$F$1141,전산회선!$B$4:$B$1141,$E10,전산회선!$F$4:$F$1141,"<"&AF10)),"") -> 2 | AI10: {=IF(AJ10="","",INDEX(전산회선!$E$4:$E$1141,_xlfn.AGGREGATE(15,6,ROW(전산회선!$E$4:$E$1141)-ROW(전산회선!$E$4)+1/((전산회선!$B$4:$B$1141=$E10)*(전산회선!$F$4:$F$1141=AJ10)),1)))} | AJ10: =IFERROR(IF(_xlfn.MAXIFS(전산회선!$F$4:$F$1141,전산회선!$B$4:$B$1141,$E10,전산회선!$F$4:$F$1141,"<"&AH10)=0,"",_xlfn.MAXIFS(전산회선!$F$4:$F$1141,전산회선!$B$4:$B$1141,$E10,전산회선!$F$4:$F$1141,"<"&AH10)),"") | AK10: {=IF(AL10="","",INDEX(전산회선!$E$4:$E$1141,_xlfn.AGGREGATE(15,6,ROW(전산회선!$E$4:$E$1141)-ROW(전산회선!$E$4)+1/((전산회선!$B$4:$B$1141=$E10)*(전산회선!$F$4:$F$1141=AL10)),1)))} | AL10: =IFERROR(IF(_xlfn.MAXIFS(전산회선!$F$4:$F$1141,전산회선!$B$4:$B$1141,$E10,전산회선!$F$4:$F$1141,"<"&AJ10)=0,"",_xlfn.MAXIFS(전산회선!$F$4:$F$1141,전산회선!$B$4:$B$1141,$E10,전산회선!$F$4:$F$1141,"<"&AJ10)),"") | AM10: {=IF(AN10="","",INDEX(전산회선!$E$4:$E$1141,_xlfn.AGGREGATE(15,6,ROW(전산회선!$E$4:$E$1141)-ROW(전산회선!$E$4)+1/((전산회선!$B$4:$B$1141=$E10)*(전산회선!$F$4:$F$1141=AN10)),1)))} | AN10: =IFERROR(IF(_xlfn.MAXIFS(전산회선!$F$4:$F$1141,전산회선!$B$4:$B$1141,$E10,전산회선!$F$4:$F$1141,"<"&AL10)=0,"",_xlfn.MAXIFS(전산회선!$F$4:$F$1141,전산회선!$B$4:$B$1141,$E10,전산회선!$F$4:$F$1141,"<"&AL10)),"") | AO10: 221102.38 | AP10: 241031.38 | AQ10: 264250.38 | AR10: 242263.38 | AS10: 275001.38 | AT10: 241528.38 | AU10: 228585.38 | AV10: 195136.83 | AW10: 208735.38 | AX10: 155740.38 | AY10: 167150.31 | AZ10: 263550.38 | BA10: 225339.67 | BB10: =SUM(AO10:AZ10) -> 2704076 | BC10: 20801 | BD10: 41962 | BE10: 41962 | BF10: 41962 | BG10: 74690 | BH10: 41962 | BI10: 41962 | BJ10: 51311 | BK10: 77919 | BL10: 24924 | BM10: 24924 | BN10: 44536 | BO10: 44076.25 | BP10: 528915 | BQ10: =IFERROR(INDEX(피벗!$BL$5:$CH$5,1,MATCH($BR10,INDEX(피벗!$BL:$CH,MATCH($E10,피벗!$BJ:$BJ,0),0),0)),"") -> GiGA인터넷 | BR10: =IFERROR(LARGE(INDEX(피벗!$BL:$CH,MATCH(성장고객!$E10,피벗!$BJ:$BJ,0),0),1),"") -> 435718 | BS10: =IFERROR(BR10/$BB10,"") -> 0.16113379 | BT10: =IFERROR(INDEX(피벗!$BL$5:$CH$5,1,MATCH($BU10,INDEX(피벗!$BL:$CH,MATCH($E10,피벗!$BJ:$BJ,0),0),0)),"") -> MeGA인터넷 | BU10: =IFERROR(LARGE(INDEX(피벗!$BL:$CH,MATCH(성장고객!$E10,피벗!$BJ:$BJ,0),0),2),"") -> 93197 | BV10: =IFERROR(BU10/$BB10,"") -> 0.034465378 | BW10: =IFERROR(INDEX(피벗!$BL$5:$CH$5,1,MATCH($BX10,INDEX(피벗!$BL:$CH,MATCH($E10,피벗!$BJ:$BJ,0),0),0)),"") | BX10: =IFERROR(LARGE(INDEX(피벗!$BL:$CH,MATCH(성장고객!$E10,피벗!$BJ:$BJ,0),0),3),"") | BY10: =IFERROR(BX10/$BB10,"") | BZ10: =IFERROR(INDEX(피벗!$BL$5:$CH$5,1,MATCH($CA10,INDEX(피벗!$BL:$CH,MATCH($E10,피벗!$BJ:$BJ,0),0),0)),"") | CA10: =IFERROR(LARGE(INDEX(피벗!$BL:$CH,MATCH(성장고객!$E10,피벗!$BJ:$BJ,0),0),4),"") | CB10: =IFERROR(CA10/$BB10,"") | CC10: =IFERROR(INDEX(피벗!$BL$5:$CH$5,1,MATCH($CD10,INDEX(피벗!$BL:$CH,MATCH($E10,피벗!$BJ:$BJ,0),0),0)),"") | CD10: =IFERROR(LARGE(INDEX(피벗!$BL:$CH,MATCH(성장고객!$E10,피벗!$BJ:$BJ,0),0),5),"") | CE10: =IFERROR(CD10/$BB10,"") | CF10: =IFERROR(INDEX(피벗!$CI:$CI,MATCH($E10,피벗!$BJ:$BJ,0)),"") -> 528915 | CG10: =IFERROR(CF10/$BB10,"") -> 0.19559916 | CH10: =IFERROR(INDEX(피벗!$EZ$5:$GE$5,1,MATCH($CI10,INDEX(피벗!$EZ:$GE,MATCH($E10,피벗!$EY:$EY,0),0),0)),"") -> GiGA인터넷 | CI10: =IFERROR(LARGE(INDEX(피벗!$EZ:$GE,MATCH(성장고객!$E10,피벗!$EY:$EY,0),0),1),"") -> 1425672 | CJ10: =IFERROR(INDEX(피벗!$EZ$5:$GE$5,1,MATCH($CK10,INDEX(피벗!$EZ:$GE,MATCH($E10,피벗!$EY:$EY,0),0),0)),"") -> MeGA인터넷 | CK10: =IFERROR(LARGE(INDEX(피벗!$EZ:$GE,MATCH(성장고객!$E10,피벗!$EY:$EY,0),0),2),"") -> 692023 | CL10: =IFERROR(INDEX(피벗!$EZ$5:$GE$5,1,MATCH($CM10,INDEX(피벗!$EZ:$GE,MATCH($E10,피벗!$EY:$EY,0),0),0)),"") -> GTV | CM10: =IFERROR(LARGE(INDEX(피벗!$EZ:$GE,MATCH(성장고객!$E10,피벗!$EY:$EY,0),0),3),"") -> 466613 | CN10: =IFERROR(INDEX(피벗!$EZ$5:$GE$5,1,MATCH($CO10,INDEX(피벗!$EZ:$GE,MATCH($E10,피벗!$EY:$EY,0),0),0)),"") -> GTV Biz | CO10: =IFERROR(LARGE(INDEX(피벗!$EZ:$GE,MATCH(성장고객!$E10,피벗!$EY:$EY,0),0),4),"") -> 71768 | CP10: =IFERROR(INDEX(피벗!$EZ$5:$GE$5,1,MATCH($CQ10,INDEX(피벗!$EZ:$GE,MATCH($E10,피벗!$EY:$EY,0),0),0)),"") -> 기가지니 TV | CQ10: =IFERROR(LARGE(INDEX(피벗!$EZ:$GE,MATCH(성장고객!$E10,피벗!$EY:$EY,0),0),5),"") -> 48000 | CR10: =IFERROR(INDEX(피벗!$GF:$GF,MATCH($E10,피벗!$EY:$EY,0)),"") -> 2704076
A11: 경북법인고객담당 | B11: 법인고객영업2부 | C11: 법인고객영업2팀 | D11: 이대석 | E11: 1-I53FFA | F11: 한맥건설(주) | G11: 법인가치고객 | H11: 본사 | I11: 1711110005240 | J11: 5088106230 | K11: 본사 | L11: 정상 | M11: 건설업 | N11: 건설/호텔 | O11: Manufacture>중공업>건설>건설업-종합 | P11: 5 | Q11: 소상공인 | R11: 주식회사 | S11: 신규설립(개업) | T11: 정상 | U11: 경북 안동시 옥동 | V11: 987-10번지 메트로오피스텔 803호 | W11: 054 852 7101 | X11: 철근콘크리트, 토공사 | Y11: 경북 안동시 복주5길 | Z11: 41, 803호 (옥동,메트로오피스텔) | AA11: 4 | AB11: BBB- | AC11: 철근 및 철근콘크리트 공사업 | AD11: 제조업 | AE11: {=IF(AF11="","",INDEX(전산회선!$E$4:$E$1141,_xlfn.AGGREGATE(15,6,ROW(전산회선!$E$4:$E$1141)-ROW(전산회선!$E$4)+1/((전산회선!$B$4:$B$1141=$E11)*(전산회선!$F$4:$F$1141=AF11)),1)))} -> 홈일반전화 | AF11: =IFERROR(IF(_xlfn.MAXIFS(전산회선!$F$4:$F$1141,전산회선!$B$4:$B$1141,$E11)=0,"",_xlfn.MAXIFS(전산회선!$F$4:$F$1141,전산회선!$B$4:$B$1141,$E11)),"") -> 3 | AG11: {=IF(AH11="","",INDEX(전산회선!$E$4:$E$1141,_xlfn.AGGREGATE(15,6,ROW(전산회선!$E$4:$E$1141)-ROW(전산회선!$E$4)+1/((전산회선!$B$4:$B$1141=$E11)*(전산회선!$F$4:$F$1141=AH11)),1)))} -> GTV | AH11: =IFERROR(IF(_xlfn.MAXIFS(전산회선!$F$4:$F$1141,전산회선!$B$4:$B$1141,$E11,전산회선!$F$4:$F$1141,"<"&AF11)=0,"",_xlfn.MAXIFS(전산회선!$F$4:$F$1141,전산회선!$B$4:$B$1141,$E11,전산회선!$F$4:$F$1141,"<"&AF11)),"") -> 1 | AI11: {=IF(AJ11="","",INDEX(전산회선!$E$4:$E$1141,_xlfn.AGGREGATE(15,6,ROW(전산회선!$E$4:$E$1141)-ROW(전산회선!$E$4)+1/((전산회선!$B$4:$B$1141=$E11)*(전산회선!$F$4:$F$1141=AJ11)),1)))} | AJ11: =IFERROR(IF(_xlfn.MAXIFS(전산회선!$F$4:$F$1141,전산회선!$B$4:$B$1141,$E11,전산회선!$F$4:$F$1141,"<"&AH11)=0,"",_xlfn.MAXIFS(전산회선!$F$4:$F$1141,전산회선!$B$4:$B$1141,$E11,전산회선!$F$4:$F$1141,"<"&AH11)),"") | AK11: {=IF(AL11="","",INDEX(전산회선!$E$4:$E$1141,_xlfn.AGGREGATE(15,6,ROW(전산회선!$E$4:$E$1141)-ROW(전산회선!$E$4)+1/((전산회선!$B$4:$B$1141=$E11)*(전산회선!$F$4:$F$1141=AL11)),1)))} | AL11: =IFERROR(IF(_xlfn.MAXIFS(전산회선!$F$4:$F$1141,전산회선!$B$4:$B$1141,$E11,전산회선!$F$4:$F$1141,"<"&AJ11)=0,"",_xlfn.MAXIFS(전산회선!$F$4:$F$1141,전산회선!$B$4:$B$1141,$E11,전산회선!$F$4:$F$1141,"<"&AJ11)),"") | AM11: {=IF(AN11="","",INDEX(전산회선!$E$4:$E$1141,_xlfn.AGGREGATE(15,6,ROW(전산회선!$E$4:$E$1141)-ROW(전산회선!$E$4)+1/((전산회선!$B$4:$B$1141=$E11)*(전산회선!$F$4:$F$1141=AN11)),1)))} | AN11: =IFERROR(IF(_xlfn.MAXIFS(전산회선!$F$4:$F$1141,전산회선!$B$4:$B$1141,$E11,전산회선!$F$4:$F$1141,"<"&AL11)=0,"",_xlfn.MAXIFS(전산회선!$F$4:$F$1141,전산회선!$B$4:$B$1141,$E11,전산회선!$F$4:$F$1141,"<"&AL11)),"") | AO11: 40789 | AP11: 41082 | AQ11: 42997 | AR11: 40809 | AS11: 41571 | AT11: 39866 | AU11: 11673 | AV11: 4702 | AW11: 16084 | AX11: 16255 | AY11: 14593 | AZ11: 18724 | BA11: 27428.75 | BB11: =SUM(AO11:AZ11) -> 329145 | BC11: 0 | BD11: 0 | BE11: 0 | BF11: 0 | BG11: 0 | BH11: 0 | BI11: 0 | BJ11: 0 | BK11: 0 | BL11: 0 | BM11: 0 | BN11: 0 | BO11: 0 | BP11: 0 | BQ11: =IFERROR(INDEX(피벗!$BL$5:$CH$5,1,MATCH($BR11,INDEX(피벗!$BL:$CH,MATCH($E11,피벗!$BJ:$BJ,0),0),0)),"") | BR11: =IFERROR(LARGE(INDEX(피벗!$BL:$CH,MATCH(성장고객!$E11,피벗!$BJ:$BJ,0),0),1),"") | BS11: =IFERROR(BR11/$BB11,"") | BT11: =IFERROR(INDEX(피벗!$BL$5:$CH$5,1,MATCH($BU11,INDEX(피벗!$BL:$CH,MATCH($E11,피벗!$BJ:$BJ,0),0),0)),"") | BU11: =IFERROR(LARGE(INDEX(피벗!$BL:$CH,MATCH(성장고객!$E11,피벗!$BJ:$BJ,0),0),2),"") | BV11: =IFERROR(BU11/$BB11,"") | BW11: =IFERROR(INDEX(피벗!$BL$5:$CH$5,1,MATCH($BX11,INDEX(피벗!$BL:$CH,MATCH($E11,피벗!$BJ:$BJ,0),0),0)),"") | BX11: =IFERROR(LARGE(INDEX(피벗!$BL:$CH,MATCH(성장고객!$E11,피벗!$BJ:$BJ,0),0),3),"") | BY11: =IFERROR(BX11/$BB11,"") | BZ11: =IFERROR(INDEX(피벗!$BL$5:$CH$5,1,MATCH($CA11,INDEX(피벗!$BL:$CH,MATCH($E11,피벗!$BJ:$BJ,0),0),0)),"") | CA11: =IFERROR(LARGE(INDEX(피벗!$BL:$CH,MATCH(성장고객!$E11,피벗!$BJ:$BJ,0),0),4),"") | CB11: =IFERROR(CA11/$BB11,"") | CC11: =IFERROR(INDEX(피벗!$BL$5:$CH$5,1,MATCH($CD11,INDEX(피벗!$BL:$CH,MATCH($E11,피벗!$BJ:$BJ,0),0),0)),"") | CD11: =IFERROR(LARGE(INDEX(피벗!$BL:$CH,MATCH(성장고객!$E11,피벗!$BJ:$BJ,0),0),5),"") | CE11: =IFERROR(CD11/$BB11,"") | CF11: =IFERROR(INDEX(피벗!$CI:$CI,MATCH($E11,피벗!$BJ:$BJ,0)),"") | CG11: =IFERROR(CF11/$BB11,"") | CH11: =IFERROR(INDEX(피벗!$EZ$5:$GE$5,1,MATCH($CI11,INDEX(피벗!$EZ:$GE,MATCH($E11,피벗!$EY:$EY,0),0),0)),"") -> 홈일반전화 | CI11: =IFERROR(LARGE(INDEX(피벗!$EZ:$GE,MATCH(성장고객!$E11,피벗!$EY:$EY,0),0),1),"") -> 170767 | CJ11: =IFERROR(INDEX(피벗!$EZ$5:$GE$5,1,MATCH($CK11,INDEX(피벗!$EZ:$GE,MATCH($E11,피벗!$EY:$EY,0),0),0)),"") -> GiGA인터넷 | CK11: =IFERROR(LARGE(INDEX(피벗!$EZ:$GE,MATCH(성장고객!$E11,피벗!$EY:$EY,0),0),2),"") -> 160577 | CL11: =IFERROR(INDEX(피벗!$EZ$5:$GE$5,1,MATCH($CM11,INDEX(피벗!$EZ:$GE,MATCH($E11,피벗!$EY:$EY,0),0),0)),"") -> GTV | CM11: =IFERROR(LARGE(INDEX(피벗!$EZ:$GE,MATCH(성장고객!$E11,피벗!$EY:$EY,0),0),3),"") -> 40643 | CN11: =IFERROR(INDEX(피벗!$EZ$5:$GE$5,1,MATCH($CO11,INDEX(피벗!$EZ:$GE,MATCH($E11,피벗!$EY:$EY,0),0),0)),"") -> 홈지능망 | CO11: =IFERROR(LARGE(INDEX(피벗!$EZ:$GE,MATCH(성장고객!$E11,피벗!$EY:$EY,0),0),4),"") -> 26400 | CP11: =IFERROR(INDEX(피벗!$EZ$5:$GE$5,1,MATCH($CQ11,INDEX(피벗!$EZ:$GE,MATCH($E11,피벗!$EY:$EY,0),0),0)),"") -> 기가지니 TV | CQ11: =IFERROR(LARGE(INDEX(피벗!$EZ:$GE,MATCH(성장고객!$E11,피벗!$EY:$EY,0),0),5),"") -> 18677 | CR11: =IFERROR(INDEX(피벗!$GF:$GF,MATCH($E11,피벗!$EY:$EY,0)),"") -> 329145
A12: 경북법인고객담당 | B12: 법인고객영업3부 | C12: 법인고객영업1팀 | D12: 고한용 | E12: A0001350851 | F12: 한두레축산영농조합법인 | G12: 법인가치고객 | H12: 본사 | I12: 1754710002447 | J12: 5118112058 | K12: 본사 | L12: 정상 | M12: 판매업 | N12: 공통 | O12: Retail/Service>도소매>생활재 판매>사료도매 | P12: 10 | Q12: 소기업 | R12: 기타법인 | S12: 신규설립(개업) | T12: 정상 | U12: 경북 문경시 산양면 | V12: 진정리 630-3번지 | W12: 054 554 1050 | X12: TMF 사료 외 | Y12: 경북 문경시 산양면 산양공단1길 | Z12: 28 (진정리) | AA12: 11 | AB12: BB- | AD12: 제조업 | AE12: {=IF(AF12="","",INDEX(전산회선!$E$4:$E$1141,_xlfn.AGGREGATE(15,6,ROW(전산회선!$E$4:$E$1141)-ROW(전산회선!$E$4)+1/((전산회선!$B$4:$B$1141=$E12)*(전산회선!$F$4:$F$1141=AF12)),1)))} -> MeGA인터넷 | AF12: =IFERROR(IF(_xlfn.MAXIFS(전산회선!$F$4:$F$1141,전산회선!$B$4:$B$1141,$E12)=0,"",_xlfn.MAXIFS(전산회선!$F$4:$F$1141,전산회선!$B$4:$B$1141,$E12)),"") -> 7 | AG12: {=IF(AH12="","",INDEX(전산회선!$E$4:$E$1141,_xlfn.AGGREGATE(15,6,ROW(전산회선!$E$4:$E$1141)-ROW(전산회선!$E$4)+1/((전산회선!$B$4:$B$1141=$E12)*(전산회선!$F$4:$F$1141=AH12)),1)))} -> 홈일반전화 | AH12: =IFERROR(IF(_xlfn.MAXIFS(전산회선!$F$4:$F$1141,전산회선!$B$4:$B$1141,$E12,전산회선!$F$4:$F$1141,"<"&AF12)=0,"",_xlfn.MAXIFS(전산회선!$F$4:$F$1141,전산회선!$B$4:$B$1141,$E12,전산회선!$F$4:$F$1141,"<"&AF12)),"") -> 3 | AI12: {=IF(AJ12="","",INDEX(전산회선!$E$4:$E$1141,_xlfn.AGGREGATE(15,6,ROW(전산회선!$E$4:$E$1141)-ROW(전산회선!$E$4)+1/((전산회선!$B$4:$B$1141=$E12)*(전산회선!$F$4:$F$1141=AJ12)),1)))} | AJ12: =IFERROR(IF(_xlfn.MAXIFS(전산회선!$F$4:$F$1141,전산회선!$B$4:$B$1141,$E12,전산회선!$F$4:$F$1141,"<"&AH12)=0,"",_xlfn.MAXIFS(전산회선!$F$4:$F$1141,전산회선!$B$4:$B$1141,$E12,전산회선!$F$4:$F$1141,"<"&AH12)),"") | AK12: {=IF(AL12="","",INDEX(전산회선!$E$4:$E$1141,_xlfn.AGGREGATE(15,6,ROW(전산회선!$E$4:$E$1141)-ROW(전산회선!$E$4)+1/((전산회선!$B$4:$B$1141=$E12)*(전산회선!$F$4:$F$1141=AL12)),1)))} | AL12: =IFERROR(IF(_xlfn.MAXIFS(전산회선!$F$4:$F$1141,전산회선!$B$4:$B$1141,$E12,전산회선!$F$4:$F$1141,"<"&AJ12)=0,"",_xlfn.MAXIFS(전산회선!$F$4:$F$1141,전산회선!$B$4:$B$1141,$E12,전산회선!$F$4:$F$1141,"<"&AJ12)),"") | AM12: {=IF(AN12="","",INDEX(전산회선!$E$4:$E$1141,_xlfn.AGGREGATE(15,6,ROW(전산회선!$E$4:$E$1141)-ROW(전산회선!$E$4)+1/((전산회선!$B$4:$B$1141=$E12)*(전산회선!$F$4:$F$1141=AN12)),1)))} | AN12: =IFERROR(IF(_xlfn.MAXIFS(전산회선!$F$4:$F$1141,전산회선!$B$4:$B$1141,$E12,전산회선!$F$4:$F$1141,"<"&AL12)=0,"",_xlfn.MAXIFS(전산회선!$F$4:$F$1141,전산회선!$B$4:$B$1141,$E12,전산회선!$F$4:$F$1141,"<"&AL12)),"") | AO12: 148177 | AP12: 149408 | AQ12: 150866 | AR12: 167167 | AS12: 170581 | AT12: 170314 | AU12: 170830 | AV12: 170795 | AW12: 171816 | AX12: 170565 | AY12: 170540 | AZ12: 171436 | BA12: 165207.92 | BB12: =SUM(AO12:AZ12) -> 1982495 | BC12: 0 | BD12: 0 | BE12: 0 | BF12: 18295 | BG12: 20962 | BH12: 20962 | BI12: 20962 | BJ12: 20962 | BK12: 20962 | BL12: 20962 | BM12: 20962 | BN12: 20962 | BO12: 15499.25 | BP12: 185991 | BQ12: =IFERROR(INDEX(피벗!$BL$5:$CH$5,1,MATCH($BR12,INDEX(피벗!$BL:$CH,MATCH($E12,피벗!$BJ:$BJ,0),0),0)),"") -> MeGA인터넷 | BR12: =IFERROR(LARGE(INDEX(피벗!$BL:$CH,MATCH(성장고객!$E12,피벗!$BJ:$BJ,0),0),1),"") -> 185991 | BS12: =IFERROR(BR12/$BB12,"") -> 0.09381663 | BT12: =IFERROR(INDEX(피벗!$BL$5:$CH$5,1,MATCH($BU12,INDEX(피벗!$BL:$CH,MATCH($E12,피벗!$BJ:$BJ,0),0),0)),"") | BU12: =IFERROR(LARGE(INDEX(피벗!$BL:$CH,MATCH(성장고객!$E12,피벗!$BJ:$BJ,0),0),2),"") | BV12: =IFERROR(BU12/$BB12,"") | BW12: =IFERROR(INDEX(피벗!$BL$5:$CH$5,1,MATCH($BX12,INDEX(피벗!$BL:$CH,MATCH($E12,피벗!$BJ:$BJ,0),0),0)),"") | BX12: =IFERROR(LARGE(INDEX(피벗!$BL:$CH,MATCH(성장고객!$E12,피벗!$BJ:$BJ,0),0),3),"") | BY12: =IFERROR(BX12/$BB12,"") | BZ12: =IFERROR(INDEX(피벗!$BL$5:$CH$5,1,MATCH($CA12,INDEX(피벗!$BL:$CH,MATCH($E12,피벗!$BJ:$BJ,0),0),0)),"") | CA12: =IFERROR(LARGE(INDEX(피벗!$BL:$CH,MATCH(성장고객!$E12,피벗!$BJ:$BJ,0),0),4),"") | CB12: =IFERROR(CA12/$BB12,"") | CC12: =IFERROR(INDEX(피벗!$BL$5:$CH$5,1,MATCH($CD12,INDEX(피벗!$BL:$CH,MATCH($E12,피벗!$BJ:$BJ,0),0),0)),"") | CD12: =IFERROR(LARGE(INDEX(피벗!$BL:$CH,MATCH(성장고객!$E12,피벗!$BJ:$BJ,0),0),5),"") | CE12: =IFERROR(CD12/$BB12,"") | CF12: =IFERROR(INDEX(피벗!$CI:$CI,MATCH($E12,피벗!$BJ:$BJ,0)),"") -> 185991 | CG12: =IFERROR(CF12/$BB12,"") -> 0.09381663 | CH12: =IFERROR(INDEX(피벗!$EZ$5:$GE$5,1,MATCH($CI12,INDEX(피벗!$EZ:$GE,MATCH($E12,피벗!$EY:$EY,0),0),0)),"") -> MeGA인터넷 | CI12: =IFERROR(LARGE(INDEX(피벗!$EZ:$GE,MATCH(성장고객!$E12,피벗!$EY:$EY,0),0),1),"") -> 1729215 | CJ12: =IFERROR(INDEX(피벗!$EZ$5:$GE$5,1,MATCH($CK12,INDEX(피벗!$EZ:$GE,MATCH($E12,피벗!$EY:$EY,0),0),0)),"") -> 홈일반전화 | CK12: =IFERROR(LARGE(INDEX(피벗!$EZ:$GE,MATCH(성장고객!$E12,피벗!$EY:$EY,0),0),2),"") -> 190880 | CL12: =IFERROR(INDEX(피벗!$EZ$5:$GE$5,1,MATCH($CM12,INDEX(피벗!$EZ:$GE,MATCH($E12,피벗!$EY:$EY,0),0),0)),"") -> 홈지능망 | CM12: =IFERROR(LARGE(INDEX(피벗!$EZ:$GE,MATCH(성장고객!$E12,피벗!$EY:$EY,0),0),3),"") -> 62400 | CN12: =IFERROR(INDEX(피벗!$EZ$5:$GE$5,1,MATCH($CO12,INDEX(피벗!$EZ:$GE,MATCH($E12,피벗!$EY:$EY,0),0),0)),"") | CO12: =IFERROR(LARGE(INDEX(피벗!$EZ:$GE,MATCH(성장고객!$E12,피벗!$EY:$EY,0),0),4),"") | CP12: =IFERROR(INDEX(피벗!$EZ$5:$GE$5,1,MATCH($CQ12,INDEX(피벗!$EZ:$GE,MATCH($E12,피벗!$EY:$EY,0),0),0)),"") | CQ12: =IFERROR(LARGE(INDEX(피벗!$EZ:$GE,MATCH(성장고객!$E12,피벗!$EY:$EY,0),0),5),"") | CR12: =IFERROR(INDEX(피벗!$GF:$GF,MATCH($E12,피벗!$EY:$EY,0)),"") -> 1982495
